Workbook

Sheet Ringkasan
A1: Analisis Distribusi Petugas Bencana - Revisi 5 (saran PPL & PML)
A2: Disusun 4 Okt 2026. Seluruhnya SARAN: tidak ada perubahan pada plotting yang sudah tersimpan.
A4: A. Jawaban inti
A5: PPL yang bisa dipakai dari data yang ada (rencana saran) | B5: =COUNTIF('Beban per PPL'!$H$5:$H$107,">0")-COUNTIF('Beban per PPL'!$C$5:$C$107,"Rekrut baru") -> 67 | D5: Termasuk 3 nama yang diminta (Amelia, ANIKE PUTRI, Annisa Suryani).
A6: PPL baru yang masih dibutuhkan (rekrut skema menginap) | B6: ='Kebutuhan PPL Tambahan'!$C$44 -> 32 | D6: Diambil dari petugas yang sudah daftar tapi belum diplot: 28 bernilai >= 4, sisanya nilai 3. Lihat sheet Kebutuhan PPL Tambahan dan Rencana Menginap.
A7: Total PPL jika semua rekrut bersedia menginap | B7: =B5+B6 -> 99 | D7: Target > 80 (tidak wajib) - terpenuhi.
A8: Rentang kebutuhan rekrut menurut skenario (min - maks) | B8: =MIN('Kebutuhan PPL Tambahan'!H49:H53) -> 17 | C8: =MAX('Kebutuhan PPL Tambahan'!H49:H53) -> 40 | D8: Tergantung seberapa longgar radius dan batas beban (sheet Kebutuhan PPL Tambahan, bagian bawah).
A9: PPL dari data yang ada memenuhi target > 80? | B9: =IF(B5>80,"Ya","Tidak (perlu rekrut)") -> Tidak (perlu rekrut) | D9: Total dengan rekrut tetap di atas 80; PPL yang ada saja kurang karena calon PML tidak dijadikan PPL.
A11: B. Di mana rekrut dibutuhkan
A12: Kecamatan | B12: Rekrut dibutuhkan | C12: Skor beban | D12: Nagari / Catatan
A13: JUNJUNG SIRIH | B13: ='Kebutuhan PPL Tambahan'!C41 -> 9 | C13: ='Kebutuhan PPL Tambahan'!D41 -> 1571.1 | D13: PANINGGAHAN (9 wilayah), MUARO PINGAI (4 wilayah)
A14: KUBUNG | B14: ='Kebutuhan PPL Tambahan'!C42 -> 12 | C14: ='Kebutuhan PPL Tambahan'!D42 -> 1411.7 | D14: SELAYO (12 wilayah)
A15: X KOTO SINGKARAK | B15: ='Kebutuhan PPL Tambahan'!C43 -> 11 | C15: ='Kebutuhan PPL Tambahan'!D43 -> 1895.5 | D15: SANIANG BAKA (7 wilayah), SUMANI (5 wilayah), KOTO SANI (1 wilayah)
A17: C. Skema PML (1 PML : 4 PPL, maks. 5)
A18: Jumlah klaster PML yang dibutuhkan | B18: =COUNTA('Saran PML'!$A$5:$A$26) -> 22 | D18: Total PPL dibagi 4-5 per klaster (11 klaster 5 PPL, 11 klaster 4 PPL).
A19: PML terisi dari calon PML (tetap menjadi PML) | B19: =COUNTIF('Saran PML'!$K$5:$K$26,"Calon PML") -> 21 | D19: Domisili PML <= 15 km dari pusat klaster; sheet Saran PML.
A20: PML yang harus diisi pegawai organik (diplot nanti) | B20: =COUNTIF('Saran PML'!$K$5:$K$26,"Organik") -> 1 | D20: Klaster tanpa calon PML dalam batas jarak (Lembah Gumanti). Hariston & Ilham calon PML bernama sama dgn 2 pegawai organik - mohon dicek.
A21: Calon PML yang dialihkan jadi PPL | B21: =COUNTIF('Beban per PPL'!$C$5:$C$107,"Calon PML dialihkan jadi PPL")+COUNTIF('Beban per PPL'!$C$5:$C$107,"Nama diminta admin") -> 3 | D21: Hanya 3 nama yang diminta (Amelia, ANIKE PUTRI, Annisa Suryani).
A22: Calon PML cadangan (belum terpasang) | B22: =COUNTIF('Direktori Petugas'!$D$5:$D$471,"Calon PML - cadangan") -> 5 | D22: Tidak bentrok kegiatan lain; bisa jadi PML pengganti atau PPL.
A24: D. Dampak pada keseimbangan beban PPL
A25: Indikator | B25: Existing | C25: Saran | D25: Keterangan
A26: Jumlah PPL berwilayah | B26: =COUNTIF('Beban per PPL'!$F$5:$F$107,">0") -> 62 | C26: =COUNTIF('Beban per PPL'!$H$5:$H$107,">0") -> 99 | D26: Saran sudah termasuk rekrut baru.
A27: Beban terbesar (skor) | B27: =MAX('Beban per PPL'!$G$5:$G$107) -> 515.77 | C27: =MAX('Beban per PPL'!$I$5:$I$107) -> 219.12
A28: Rata-rata beban (skor) | B28: =AVERAGEIF('Beban per PPL'!$F$5:$F$107,">0",'Beban per PPL'!$G$5:$G$107) -> 191.25065 | C28: =AVERAGEIF('Beban per PPL'!$H$5:$H$107,">0",'Beban per PPL'!$I$5:$I$107) -> 159.54596
A29: Simpangan baku beban (skor) | B29: =SQRT((SUMPRODUCT(('Beban per PPL'!$F$5:$F$107>0)*'Beban per PPL'!$G$5:$G$107^2)-COUNTIF('Beban per PPL'!$F$5:$F$107,">0")*B28^2)/(COUNTIF('Beban per PPL'!$F$5:$F$107,">0")-1)) -> 103.57997 | C29: =SQRT((SUMPRODUCT(('Beban per PPL'!$H$5:$H$107>0)*'Beban per PPL'!$I$5:$I$107^2)-COUNTIF('Beban per PPL'!$H$5:$H$107,">0")*C28^2)/(COUNTIF('Beban per PPL'!$H$5:$H$107,">0")-1)) -> 44.645466 | D29: Semakin kecil semakin merata.
A30: PPL dengan beban > maksimal | B30: =COUNTIF('Beban per PPL'!$G$5:$G$107,">"&'Parameter & Asumsi'!$B$8) -> 25 | C30: =COUNTIF('Beban per PPL'!$I$5:$I$107,">"&'Parameter & Asumsi'!$B$8) -> 0 | D30: Maksimal mengacu ke sheet Parameter & Asumsi.
A32: E. Skema menginap untuk rekrutan baru
A33: Petugas terdaftar (belum diplot) yang ditawari menginap | B33: ='Rencana Menginap'!$C$10 -> 32 | D33: Penerima tawaran per lokasi ada di sheet Rencana Menginap, lengkap dengan kolom jawaban.
A34: Lokasi kontrakan BPS yang dibutuhkan | B34: =COUNTA('Rencana Menginap'!$B$5:$B$9) -> 5 | D34: Satu kontrakan per nagari pusat wilayah (Muaro Pingai, Paninggahan, Selayo, Saniang Baka, Sumani).
A35: Cadangan (terdaftar, belum diplot, tidak terpilih) | B35: =COUNTIF('Direktori Petugas'!$D$5:$D$471,"Cadangan menginap*") -> 9 | D35: Dipakai bila ada yang menolak menginap; sebagian belum dinilai.
A37: F. Perubahan atas permintaan
A38: 1. Catatan 'sudah diplot tapi ikut kegiatan lain (SPDT NTP 2026)' diganti dengan calon lain - sheet Ganti Bentrok (Norlizah, ELSI FEBRIANI, Rona Afriyeni, DANA NOKELADIO; dua yang terakhir belum punya wilayah, disarankan cabut peran PPL).
A39: 2. Kolom 'Skor Beban PPL Saran (total)' ditambahkan di sheet Existing vs Saran, dan perbandingan lengkap per PPL di sheet Beban per PPL.
A40: 3. Amelia, ANIKE PUTRI, Annisa Suryani ditetapkan sebagai PPL (wilayah terdekat) - lihat filter Sumber 'Nama diminta admin'.
A41: 4. Nama rekrut untuk tiap slot PPL baru + alternatif ada di sheet Kebutuhan PPL Tambahan; saran klaster & PML di sheet Saran PML dan Anggota Klaster PML.
A42: 5. Revisi 5: kebutuhan rekrut kini diisi dari petugas yang sudah daftar tapi belum diplot, dengan tawaran menginap di kontrakan BPS (sheet Rencana Menginap memuat daftar penerima tawaran per lokasi, kolom jawaban, dan contoh pesan).
A43: 6. Revisi 4: PPL berbeban terlalu kecil (< 60 skor) digabung - satu PPL yang lebih dekat/layak memegang wilayah keduanya (lihat Jenis Perubahan 'Gabung' di sheet Existing vs Saran dan Catatan di Beban per PPL).
A44: 7. Catatan: angka beban Clara Amelya Hendres (48,9) dan Indri septiadi (22,5) berasal dari Revisi 2; di revisi ini beban keduanya sudah 204,5 dan 150,3 karena tidak ada lagi calon PML yang mengambil wilayahnya.
A45: 8. Revisi 3: calon PML dipertahankan sebagai PML (21 terpasang di 22 klaster + 5 cadangan); hanya 3 nama yang diminta dijadikan PPL. Konsekuensinya rekrut PPL baru naik dari 17 menjadi 32.

Sheet Kebutuhan PPL Tambahan
A1: Kebutuhan PPL Tambahan - rekrut dari petugas yang sudah daftar tapi belum diplot, dengan skema MENGINAP
A2: Slot = 1 orang PPL yang dibutuhkan agar semua Sub SLS terpegang dengan beban wajar. Kandidat utama = petugas terdaftar yang belum mendapat wilayah; ditawari menginap di kontrakan BPS di lokasi pendataan (tanpa pulang-pergi) bersama rekan PPL lain, sehingga jarak domisili tidak lagi membatasi.
A4: No | B4: Kecamatan | C4: Nagari | D4: Sub SLS yang dicakup | E4: Skor Beban Slot | F4: Kandidat Utama (ditawari menginap) | G4: ID | H4: Nilai | I4: Jarak Domisili ke Wilayah (km) | J4: Lokasi Domisili | K4: Sudah Daftar Bencana? | L4: No HP | M4: Cadangan 1 | N4: Cadangan 2 | O4: Cadangan 3 | P4: Jumlah Kandidat Terdaftar yang Layak (nilai>=4) | Q4: Lokasi Menginap (kontrakan BPS)
A5: 1 | B5: JUNJUNG SIRIH | C5: PANINGGAHAN | D5: JORONG GANDO /04 | E5: 156 | F5: Badrizal | G5: 44 | H5: 5 | I5: 48.03 | J5: Perkiraan (kecamatan) | K5: Sudah | L5: +6281275622782 | M5: Roza Novrika Sari (1.0 km, nilai None, -) | N5: Khairani Permata Wahyu (6.6 km, nilai None, -) | O5: Gustin Ekawati (20.5 km, nilai None, -) | P5: 28 | Q5: Nagari PANINGGAHAN, Kec. JUNJUNG SIRIH
A6: 2 | B6: JUNJUNG SIRIH | C6: PANINGGAHAN | D6: JORONG GANDO /03 | E6: 155.3 | F6: Julia Lara Zamzamy | G6: 99 | H6: 5 | I6: 40.12 | J6: Titik riil | K6: Sudah | L6: +6285836071436 | M6: Roza Novrika Sari (1.6 km, nilai None, -) | N6: Khairani Permata Wahyu (6.6 km, nilai None, -) | O6: Gustin Ekawati (20.2 km, nilai None, -) | P6: 28 | Q6: Nagari PANINGGAHAN, Kec. JUNJUNG SIRIH
A7: 3 | B7: JUNJUNG SIRIH | C7: PANINGGAHAN | D7: JORONG GANDO /05; JORONG PARUMAHAN /04 | E7: 218.6 | F7: Weza Deftalia | G7: 65 | H7: 4 | I7: 44.81 | J7: Titik riil | K7: Sudah | L7: +6282389879707 | M7: Roza Novrika Sari (0.1 km, nilai None, -) | N7: Khairani Permata Wahyu (7.2 km, nilai None, -) | O7: Gustin Ekawati (21.4 km, nilai None, -) | P7: 28 | Q7: Nagari PANINGGAHAN, Kec. JUNJUNG SIRIH
A8: 4 | B8: JUNJUNG SIRIH | C8: PANINGGAHAN | D8: JORONG GANDO /06 | E8: 155.1 | F8: NIA FEBRIWENI | G8: 283 | H8: 4 | I8: 59.26 | J8: Perkiraan (nagari) | K8: Sudah | L8: +6282285119219 | M8: Roza Novrika Sari (1.0 km, nilai None, -) | N8: Khairani Permata Wahyu (6.3 km, nilai None, -) | O8: Gustin Ekawati (20.5 km, nilai None, -) | P8: 28 | Q8: Nagari PANINGGAHAN, Kec. JUNJUNG SIRIH
A9: 5 | B9: JUNJUNG SIRIH | C9: MUARO PINGAI, PANINGGAHAN | D9: JORONG GUCI II /00 (porsi 2); JORONG PARUMAHAN /05 | E9: 213 | F9: Wahyu Isman Asmi | G9: 380 | H9: 5 | I9: 79.66 | J9: Titik riil | K9: Sudah | L9: +6281324102700 | M9: Roza Novrika Sari (1.1 km, nilai None, -) | N9: Khairani Permata Wahyu (6.3 km, nilai None, -) | O9: Gustin Ekawati (20.7 km, nilai None, -) | P9: 28 | Q9: Nagari MUARO PINGAI, Kec. JUNJUNG SIRIH
A10: 6 | B10: JUNJUNG SIRIH | C10: MUARO PINGAI | D10: JORONG GUCI II /00 (porsi 3) | E10: 143.2 | F10: Hafni Syamfitria | G10: 365 | H10: 5 | I10: 35.26 | J10: Titik riil | K10: Sudah | L10: +6282364860590 | M10: Roza Novrika Sari (1.9 km, nilai None, -) | N10: Khairani Permata Wahyu (5.6 km, nilai None, -) | O10: Gustin Ekawati (20.1 km, nilai None, -) | P10: 28 | Q10: Nagari MUARO PINGAI, Kec. JUNJUNG SIRIH
A11: 7 | B11: JUNJUNG SIRIH | C11: PANINGGAHAN | D11: JORONG SUBARANG /01; JORONG SUBARANG /03 | E11: 209.7 | F11: Febri Handayani | G11: 389 | H11: 4 | I11: 13.69 | J11: Perkiraan (kecamatan) | K11: Sudah | L11: +6281365092925 | M11: Roza Novrika Sari (1.9 km, nilai None, -) | N11: Khairani Permata Wahyu (9.1 km, nilai None, -) | O11: Gustin Ekawati (23.2 km, nilai None, -) | P11: 28 | Q11: Nagari PANINGGAHAN, Kec. JUNJUNG SIRIH
A12: 8 | B12: JUNJUNG SIRIH | C12: MUARO PINGAI, PANINGGAHAN | D12: JORONG PANYALAI /00 (porsi 2); JORONG SUBARANG /04 | E12: 205.5 | F12: NOVA ALIZA | G12: 153 | H12: 5 | I12: 22.41 | J12: Titik riil | K12: Sudah | L12: +6285199567959 | M12: Roza Novrika Sari (0.6 km, nilai None, -) | N12: Khairani Permata Wahyu (7.2 km, nilai None, -) | O12: Gustin Ekawati (21.6 km, nilai None, -) | P12: 28 | Q12: Nagari MUARO PINGAI, Kec. JUNJUNG SIRIH
A13: 9 | B13: JUNJUNG SIRIH | C13: MUARO PINGAI | D13: JORONG KOTO /00 (porsi 2) | E13: 114.7 | F13: Kodratur rahman | G13: 276 | H13: 3 | I13: 64.05 | J13: Titik riil | K13: Sudah | L13: +6282387374685 | M13: Roza Novrika Sari (2.4 km, nilai None, -) | N13: Khairani Permata Wahyu (5.0 km, nilai None, -) | O13: Gustin Ekawati (19.4 km, nilai None, -) | P13: 28 | Q13: Nagari MUARO PINGAI, Kec. JUNJUNG SIRIH
A14: 10 | B14: KUBUNG | C14: SELAYO | D14: JORONG SAWAH SUDUT /08 (porsi 2) | E14: 128.2 | F14: Dini Fonika Putri | G14: 255 | H14: 4 | I14: 40.77 | J14: Perkiraan (kecamatan) | K14: Sudah | L14: +6283867137737 | M14: Gustin Ekawati (2.1 km, nilai None, -) | N14: Larisa Dita Putri (2.1 km, nilai None, -) | O14: Leni Marta (2.1 km, nilai None, -) | P14: 28 | Q14: Nagari SELAYO, Kec. KUBUNG
A15: 11 | B15: KUBUNG | C15: SELAYO | D15: JORONG SAWAH SUDUT /03 (porsi 1) | E15: 120.6 | F15: Nindi Oktaviana | G15: 284 | H15: 4 | I15: 30.37 | J15: Titik riil | K15: Sudah | L15: +628976579438 | M15: Gustin Ekawati (2.1 km, nilai None, -) | N15: Larisa Dita Putri (2.1 km, nilai None, -) | O15: Leni Marta (2.1 km, nilai None, -) | P15: 28 | Q15: Nagari SELAYO, Kec. KUBUNG
A16: 12 | B16: KUBUNG | C16: SELAYO | D16: JORONG SAWAH SUDUT /03 (porsi 2) | E16: 120.6 | F16: Siti Oktavia | G16: 457 | H16: 4 | I16: 31.1 | J16: Titik riil | K16: Sudah | L16: +6283181393485 | M16: Gustin Ekawati (2.1 km, nilai None, -) | N16: Larisa Dita Putri (2.1 km, nilai None, -) | O16: Leni Marta (2.1 km, nilai None, -) | P16: 28 | Q16: Nagari SELAYO, Kec. KUBUNG
... A36: 32 | B36: X KOTO SINGKARAK | C36: SANIANG BAKA | D36: JORONG AIA ANGEK /00 | E36: 98.1 | F36: Berni desriyanti | G36: 77 | H36: 5 | I36: 25.8 | J36: Titik riil | K36: Sudah | L36: +6285374078252 | M36: Roza Novrika Sari (4.1 km, nilai None, -) | N36: Khairani Permata Wahyu (5.3 km, nilai None, -) | O36: Gustin Ekawati (17.9 km, nilai None, -) | P36: 28 | Q36: Nagari SANIANG BAKA, Kec. X KOTO SINGKARAK
B39: Ringkasan per kecamatan
B40: Kecamatan | C40: Rekrut dibutuhkan | D40: Total skor beban
B41: JUNJUNG SIRIH | C41: =COUNTIF($B$5:$B$36,B41) -> 9 | D41: =SUMIF($B$5:$B$36,B41,$E$5:$E$36) -> 1571.1
B42: KUBUNG | C42: =COUNTIF($B$5:$B$36,B42) -> 12 | D42: =SUMIF($B$5:$B$36,B42,$E$5:$E$36) -> 1411.7
B43: X KOTO SINGKARAK | C43: =COUNTIF($B$5:$B$36,B43) -> 11 | D43: =SUMIF($B$5:$B$36,B43,$E$5:$E$36) -> 1895.5
B44: Total | C44: =SUM(C41:C43) -> 32 | D44: =SUM(D41:D43) -> 4878.3
B47: Sensitivitas kebutuhan rekrut terhadap parameter (hasil simulasi ulang; skenario A = dipakai di sheet lain; semua skenario A-E sudah menggabungkan PPL berbeban terlalu kecil)
B48: Skenario | C48: Radius normal (km) | D48: Radius perluasan (km) | E48: Beban ideal/PPL (skor) | F48: Beban maks/PPL (skor) | G48: PPL terpakai dari data yg ada | H48: Rekrut baru dibutuhkan | I48: Total PPL | J48: PPL > beban maks | K48: Beban maks (skor) | L48: Calon PML jadi PPL | M48: Rekrut: Junjung Sirih | N48: Rekrut: X Koto Singkarak | O48: Rekrut: Kubung
B49: A - dasar (7/10 km, 180/220) | C49: 7 | D49: 10 | E49: 180 | F49: 220 | G49: 67 | H49: 32 | I49: =G49+H49 -> 99 | J49: 0 | K49: 219.1 | L49: 3 | M49: 9 | N49: 11 | O49: 12
B50: B - beban lebih longgar (200/250) | C50: 7 | D50: 10 | E50: 200 | F50: 250 | G50: 64 | H50: 20 | I50: =G50+H50 -> 84 | J50: 0 | K50: 249.6 | L50: 3 | M50: 8 | N50: 10 | O50: 2
B51: C - radius lebih luas (10/15 km) | C51: 10 | D51: 15 | E51: 180 | F51: 220 | G51: 72 | H51: 20 | I51: =G51+H51 -> 92 | J51: 0 | K51: 219.1 | L51: 3 | M51: 9 | N51: 9 | O51: 2
B52: D - beban lebih ringan (160/200) | C52: 7 | D52: 10 | E52: 160 | F52: 200 | G52: 66 | H52: 40 | I52: =G52+H52 -> 106 | J52: 0 | K52: 199.9 | L52: 3 | M52: 10 | N52: 16 | O52: 14
B53: E - radius luas + beban longgar | C53: 10 | D53: 15 | E53: 200 | F53: 250 | G53: 67 | H53: 17 | I53: =G53+H53 -> 84 | J53: 0 | K53: 249.5 | L53: 3 | M53: 8 | N53: 9 | O53: 0
B54: Pembanding: Revisi 2 (calon PML boleh jadi PPL, dasar A) | C54: 7 | D54: 10 | E54: 180 | F54: 220 | G54: 86 | H54: 17 | I54: =G54+H54 -> 103 | J54: 4 | K54: 248.6 | L54: 19 | M54: 8 | N54: 8 | O54: 1
B55: Pembanding: Revisi 3 (dasar A, tanpa penggabungan beban kecil) | C55: 7 | D55: 10 | E55: 180 | F55: 220 | G55: 71 | H55: 32 | I55: =G55+H55 -> 103 | J55: 0 | K55: 219.1 | L55: 3 | M55: 9 | N55: 11 | O55: 12

Sheet Rencana Menginap
A1: Rencana Tawaran Menginap - Kontrakan BPS di Lokasi Pendataan
A2: Penerima tawaran = petugas yang sudah daftar tapi belum mendapat wilayah. Kolom jawaban (biru, kuning) diisi admin. Tawaran per lokasi bisa langsung dibuat di fitur 'Tawaran Menginap' pada aplikasi (kecamatan + nagari + keterangan, pilih kandidat).
A4: Kecamatan | B4: Lokasi Kontrakan (Nagari) | C4: Jumlah PPL Menginap | D4: Total Skor Beban | E4: Laki-laki | F4: Perempuan | G4: Belum diisi | H4: Jarak Domisili Rata-rata (km) | I4: Jarak Domisili Terjauh (km) | J4: Teks Keterangan Tawaran (salin ke aplikasi)
A5: JUNJUNG SIRIH | B5: MUARO PINGAI | C5: =COUNTIF($B$15:$B$46,B5) -> 4 | D5: =SUMIF($B$15:$B$46,B5,$L$15:$L$46) -> 676.4 | E5: =COUNTIFS($B$15:$B$46,B5,$E$15:$E$46,"Laki-laki") -> 2 | F5: =COUNTIFS($B$15:$B$46,B5,$E$15:$E$46,"Perempuan") -> 2 | G5: =COUNTIFS($B$15:$B$46,B5,$E$15:$E$46,"belum diisi") -> 0 | H5: =AVERAGEIF($B$15:$B$46,B5,$I$15:$I$46) -> 50.345 | I5: 79.7 | J5: Kebutuhan PPL di Nagari MUARO PINGAI, Kec. JUNJUNG SIRIH - tawarkan skema menginap di kontrakan yang disediakan BPS Kabupaten Solok selama pendataan (10-31 Okt 2026) bersama rekan PPL lain, tanpa pulang-pergi. Jam kerja 5-7 jam per hari.
A6: JUNJUNG SIRIH | B6: PANINGGAHAN | C6: =COUNTIF($B$15:$B$46,B6) -> 5 | D6: =SUMIF($B$15:$B$46,B6,$L$15:$L$46) -> 894.7 | E6: =COUNTIFS($B$15:$B$46,B6,$E$15:$E$46,"Laki-laki") -> 1 | F6: =COUNTIFS($B$15:$B$46,B6,$E$15:$E$46,"Perempuan") -> 4 | G6: =COUNTIFS($B$15:$B$46,B6,$E$15:$E$46,"belum diisi") -> 0 | H6: =AVERAGEIF($B$15:$B$46,B6,$I$15:$I$46) -> 41.182 | I6: 59.3 | J6: Kebutuhan PPL di Nagari PANINGGAHAN, Kec. JUNJUNG SIRIH - tawarkan skema menginap di kontrakan yang disediakan BPS Kabupaten Solok selama pendataan (10-31 Okt 2026) bersama rekan PPL lain, tanpa pulang-pergi. Jam kerja 5-7 jam per hari.
A7: KUBUNG | B7: SELAYO | C7: =COUNTIF($B$15:$B$46,B7) -> 12 | D7: =SUMIF($B$15:$B$46,B7,$L$15:$L$46) -> 1411.7 | E7: =COUNTIFS($B$15:$B$46,B7,$E$15:$E$46,"Laki-laki") -> 1 | F7: =COUNTIFS($B$15:$B$46,B7,$E$15:$E$46,"Perempuan") -> 7 | G7: =COUNTIFS($B$15:$B$46,B7,$E$15:$E$46,"belum diisi") -> 4 | H7: =AVERAGEIF($B$15:$B$46,B7,$I$15:$I$46) -> 32.498333 | I7: 55.9 | J7: Kebutuhan PPL di Nagari SELAYO, Kec. KUBUNG - tawarkan skema menginap di kontrakan yang disediakan BPS Kabupaten Solok selama pendataan (10-31 Okt 2026) bersama rekan PPL lain, tanpa pulang-pergi. Jam kerja 5-7 jam per hari.
A8: X KOTO SINGKARAK | B8: SANIANG BAKA | C8: =COUNTIF($B$15:$B$46,B8) -> 7 | D8: =SUMIF($B$15:$B$46,B8,$L$15:$L$46) -> 1134.5 | E8: =COUNTIFS($B$15:$B$46,B8,$E$15:$E$46,"Laki-laki") -> 1 | F8: =COUNTIFS($B$15:$B$46,B8,$E$15:$E$46,"Perempuan") -> 6 | G8: =COUNTIFS($B$15:$B$46,B8,$E$15:$E$46,"belum diisi") -> 0 | H8: =AVERAGEIF($B$15:$B$46,B8,$I$15:$I$46) -> 35.09 | I8: 70.1 | J8: Kebutuhan PPL di Nagari SANIANG BAKA, Kec. X KOTO SINGKARAK - tawarkan skema menginap di kontrakan yang disediakan BPS Kabupaten Solok selama pendataan (10-31 Okt 2026) bersama rekan PPL lain, tanpa pulang-pergi. Jam kerja 5-7 jam per hari.
A9: X KOTO SINGKARAK | B9: SUMANI | C9: =COUNTIF($B$15:$B$46,B9) -> 4 | D9: =SUMIF($B$15:$B$46,B9,$L$15:$L$46) -> 761 | E9: =COUNTIFS($B$15:$B$46,B9,$E$15:$E$46,"Laki-laki") -> 1 | F9: =COUNTIFS($B$15:$B$46,B9,$E$15:$E$46,"Perempuan") -> 3 | G9: =COUNTIFS($B$15:$B$46,B9,$E$15:$E$46,"belum diisi") -> 0 | H9: =AVERAGEIF($B$15:$B$46,B9,$I$15:$I$46) -> 40.1175 | I9: 47.6 | J9: Kebutuhan PPL di Nagari SUMANI, Kec. X KOTO SINGKARAK - tawarkan skema menginap di kontrakan yang disediakan BPS Kabupaten Solok selama pendataan (10-31 Okt 2026) bersama rekan PPL lain, tanpa pulang-pergi. Jam kerja 5-7 jam per hari.
A10: Total | C10: =SUM(C5:C9) -> 32 | D10: =SUM(D5:D9) -> 4878.3 | E10: =SUM(E5:E9) -> 6 | F10: =SUM(F5:F9) -> 22 | G10: =SUM(G5:G9) -> 4
A13: Daftar penerima tawaran per lokasi
A14: Kecamatan Lokasi | B14: Lokasi Kontrakan (Nagari) | C14: Nama | D14: ID | E14: Jenis Kelamin | F14: Umur | G14: Bisa Motor | H14: Domisili (Kec. / Nagari) | I14: Jarak Domisili ke Lokasi (km) | J14: Nilai | K14: Wilayah yang Dipegang (Sub SLS) | L14: Skor Beban | M14: No HP | N14: Bersedia menginap? (Ya/Tidak) - isi admin | O14: Catatan jawaban - isi admin
A15: JUNJUNG SIRIH | B15: MUARO PINGAI | C15: Wahyu Isman Asmi | D15: 380 | E15: Laki-laki | F15: 29 | G15: Ya | H15: TIGO LURAH / GARABAK DATA | I15: 79.66 | J15: 5 | K15: JORONG GUCI II /00; JORONG PARUMAHAN /05 | L15: 213 | M15: +6281324102700
A16: JUNJUNG SIRIH | B16: MUARO PINGAI | C16: Hafni Syamfitria | D16: 365 | E16: Perempuan | F16: 35 | G16: Ya | H16: PAYUNG SEKAKI / AIA LUO | I16: 35.26 | J16: 5 | K16: JORONG GUCI II /00 | L16: 143.2 | M16: +6282364860590
A17: JUNJUNG SIRIH | B17: MUARO PINGAI | C17: NOVA ALIZA | D17: 153 | E17: Perempuan | F17: 24 | G17: Ya | H17: IX KOTO SUNGAI LASI / INDUDUA | I17: 22.41 | J17: 5 | K17: JORONG PANYALAI /00; JORONG SUBARANG /04 | L17: 205.5 | M17: +6285199567959
A18: JUNJUNG SIRIH | B18: MUARO PINGAI | C18: Kodratur rahman | D18: 276 | E18: Laki-laki | F18: 27 | G18: Ya | H18: LEMBAH GUMANTI / AIE DINGIN | I18: 64.05 | J18: 3 | K18: JORONG KOTO /00 | L18: 114.7 | M18: +6282387374685
A19: JUNJUNG SIRIH | B19: PANINGGAHAN | C19: Badrizal | D19: 44 | E19: Laki-laki | F19: 30 | G19: Ya | H19: DANAU KEMBAR / KAMPUANG BATU DALAM | I19: 48.03 | J19: 5 | K19: JORONG GANDO /04 | L19: 156 | M19: +6281275622782
A20: JUNJUNG SIRIH | B20: PANINGGAHAN | C20: Julia Lara Zamzamy | D20: 99 | E20: Perempuan | F20: 30 | G20: Ya | H20: GUNUNG TALANG / AIA BATUMBUAK | I20: 40.12 | J20: 5 | K20: JORONG GANDO /03 | L20: 155.3 | M20: +6285836071436
A21: JUNJUNG SIRIH | B21: PANINGGAHAN | C21: Weza Deftalia | D21: 65 | E21: Perempuan | F21: 23 | G21: Ya | H21: DANAU KEMBAR / KAMPUANG BATU DALAM | I21: 44.81 | J21: 4 | K21: JORONG GANDO /05; JORONG PARUMAHAN /04 | L21: 218.6 | M21: +6282389879707
A22: JUNJUNG SIRIH | B22: PANINGGAHAN | C22: NIA FEBRIWENI | D22: 283 | E22: Perempuan | F22: 27 | G22: Ya | H22: LEMBAH GUMANTI / AIE DINGIN | I22: 59.26 | J22: 4 | K22: JORONG GANDO /06 | L22: 155.1 | M22: +6282285119219
A23: JUNJUNG SIRIH | B23: PANINGGAHAN | C23: Febri Handayani | D23: 389 | E23: Perempuan | F23: 40 | G23: Ya | H23: X KOTO DIATAS / KUNCIA | I23: 13.69 | J23: 4 | K23: JORONG SUBARANG /01; JORONG SUBARANG /03 | L23: 209.7 | M23: +6281365092925
A24: KUBUNG | B24: SELAYO | C24: Dini Fonika Putri | D24: 255 | E24: belum diisi | G24: belum diisi | H24: LEMBAH GUMANTI / - | I24: 40.77 | J24: 4 | K24: JORONG SAWAH SUDUT /08 | L24: 128.2 | M24: +6283867137737
A25: KUBUNG | B25: SELAYO | C25: Nindi Oktaviana | D25: 284 | E25: belum diisi | G25: belum diisi | H25: LEMBAH GUMANTI / - | I25: 30.37 | J25: 4 | K25: JORONG SAWAH SUDUT /03 | L25: 120.6 | M25: +628976579438
A26: KUBUNG | B26: SELAYO | C26: Siti Oktavia | D26: 457 | E26: belum diisi | G26: belum diisi | H26: - / - | I26: 31.1 | J26: 4 | K26: JORONG SAWAH SUDUT /03 | L26: 120.6 | M26: +6283181393485
A27: KUBUNG | B27: SELAYO | C27: Sherli Handayani | D27: 60 | E27: Perempuan | F27: 34 | G27: Ya | H27: DANAU KEMBAR / KAMPUANG BATU DALAM | I27: 20.49 | J27: 5 | K27: JORONG SAWAH SUDUT /06 | L27: 119.7 | M27: +6285211620712
A28: KUBUNG | B28: SELAYO | C28: Nurul Fadila Ramadhani | D28: 138 | E28: Perempuan | F28: 20 | G28: Ya | H28: HILIRAN GUMANTI / TALANG BABUNGO | I28: 39.66 | J28: 5 | K28: JORONG GALANGGANG TANGAH /07 | L28: 118.8 | M28: +6282286059710
A29: KUBUNG | B29: SELAYO | C29: Resi Linda Putri | D29: 291 | E29: belum diisi | G29: belum diisi | H29: LEMBAH GUMANTI / - | I29: 27.03 | J29: 4 | K29: JORONG GALANGGANG TANGAH /03 | L29: 117 | M29: +6282228502224
A30: KUBUNG | B30: SELAYO | C30: Witri Nadia Devita Sari | D30: 303 | E30: Perempuan | F30: 25 | G30: Ya | H30: LEMBAH GUMANTI / SUNGAI NANAM | I30: 28.11 | J30: 4 | K30: JORONG SAWAH SUDUT /01 | L30: 117 | M30: +6285363468546
A31: KUBUNG | B31: SELAYO | C31: Syafika Amalia | D31: 357 | E31: Perempuan | F31: 25 | G31: Ya | H31: PANTAI CERMIN / SURIAN | I31: 55.57 | J31: 5 | K31: JORONG SAWAH SUDUT /01 | L31: 117 | M31: +6282286552343
A32: KUBUNG | B32: SELAYO | C32: Afdhal Rezeki | D32: 309 | E32: Laki-laki | F32: 26 | G32: Ya | H32: LEMBANG JAYA / KOTO ANAU | I32: 15 | J32: 4 | K32: JORONG SAWAH SUDUT /02 | L32: 115.8 | M32: +6282283507200
A33: KUBUNG | B33: SELAYO | C33: Iza Mutiarana | D33: 344 | E33: Perempuan | F33: 29 | G33: Ya | H33: PANTAI CERMIN / SURIAN | I33: 55.91 | J33: 5 | K33: JORONG SAWAH SUDUT /02 | L33: 115.8 | M33: +6281270419996
A34: KUBUNG | B34: SELAYO | C34: FELIA NOVELIZA | D34: 262 | E34: Perempuan | F34: 26 | G34: Ya | H34: LEMBAH GUMANTI / SALIMPEK | I34: 34.83 | J34: 4 | K34: JORONG GALANGGANG TANGAH /04 | L34: 111.2 | M34: +6282288368313
A35: KUBUNG | B35: SELAYO | C35: Nurpatri | D35: 324 | E35: Perempuan | F35: 42 | G35: Tidak | H35: LEMBANG JAYA / BATU BANYAK | I35: 11.14 | J35: 4 | K35: JORONG GALANGGANG TANGAH /08 | L35: 110 | M35: +6281378702534
A36: X KOTO SINGKARAK | B36: SANIANG BAKA | C36: Alhammah Alam 'Gina | D36: 310 | E36: Perempuan | F36: 22 | G36: Ya | H36: LEMBANG JAYA / KOTO ANAU | I36: 28.5 | J36: 4 | K36: JORONG BALAI BATINGKAH /01 | L36: 216.7 | M36: +6281261493324
A37: X KOTO SINGKARAK | B37: SANIANG BAKA | C37: Sukma Yuliandra Putri | D37: 330 | E37: Perempuan | F37: 25 | G37: Ya | H37: LEMBANG JAYA / SALAYO TANANG BUKIK SILEH | I37: 33.3 | J37: 3 | K37: JORONG BALAI BATINGKAH /03 | L37: 216.7 | M37: +6285363564871
A38: X KOTO SINGKARAK | B38: SANIANG BAKA | C38: Debi Wulandari | D38: 340 | E38: Perempuan | F38: 30 | G38: Ya | H38: PANTAI CERMIN / SURIAN | I38: 70.07 | J38: 5 | K38: JORONG BALAI PANJANG /01 | L38: 139.6 | M38: +6281267118982
A39: X KOTO SINGKARAK | B39: SANIANG BAKA | C39: Adri yoy marten | D39: 308 | E39: Laki-laki | F39: 48 | G39: Ya | H39: LEMBANG JAYA / KOTO LAWEH | I39: 29.52 | J39: 3 | K39: JORONG BALAI LALANG /01 | L39: 138.4 | M39: +6283852520866
A40: X KOTO SINGKARAK | B40: SANIANG BAKA | C40: desi warni | D40: 363 | E40: Perempuan | F40: 42 | G40: Ya | H40: PAYUNG SEKAKI / SIRUKAM | I40: 28.8 | J40: 5 | K40: JORONG BALAI LALANG /02 | L40: 137.4 | M40: +6282285033028
A41: X KOTO SINGKARAK | B41: SANIANG BAKA | C41: Velmarniati | D41: 334 | E41: Perempuan | F41: 26 | G41: Ya | H41: LEMBANG JAYA / BATU BAJANJANG | I41: 29.64 | J41: 5 | K41: JORONG BALAI PANJANG /02; JORONG LIMO NINIK /01 | L41: 187.6 | M41: +6282172061511
... A46: X KOTO SINGKARAK | B46: SUMANI | C46: WENI DESTI | D46: 382 | E46: Perempuan | F46: 22 | G46: Ya | H46: TIGO LURAH / RANGKIANG LULUIH | I46: 42.21 | J46: 4 | K46: JORONG GUCI /02; JORONG SIKUMBANG /03 | L46: 215 | M46: +6282172904394
A49: Cadangan (terdaftar, belum diplot, tidak terpilih)
...

Sheet Saran PML
A1: Saran Klaster PML (1 PML membawahi 4 PPL, maksimal 5)
A2: 22 klaster dibentuk dari kedekatan pusat wilayah kerja PPL (boleh lintas kecamatan yang berdekatan). Calon PML TIDAK dijadikan PPL (kecuali 3 nama yang diminta), lalu dicocokkan ke klaster berdasarkan jarak domisili ke pusat klaster (<= 15 km). Klaster tanpa calon PML dekat diisi pegawai organik yang diplot nanti.
A4: Klaster | B4: Kecamatan | C4: Jumlah PPL | D4: Anggota PPL | E4: Total Beban Klaster (skor) | F4: Radius Klaster (km) | G4: Saran PML | H4: ID PML | I4: Jarak PML ke Pusat Klaster (km) | J4: Nilai PML | K4: Status PML | L4: Catatan
A5: K-01 | B5: GUNUNG TALANG | C5: 5 | D5: Diana Endang Pratiwi; FEBRIA RAMANITA; Mardiati; Sonya aldes fatma; Valina alsisri | E5: 575.3 | F5: 13.9 | G5: Ilham | H5: 458 | I5: 4.5359284 | K5: Calon PML | L5: Nama sama dgn pegawai organik (cek apakah orang yg sama); Belum konfirmasi bencana; Belum dinilai
A6: K-02 | B6: GUNUNG TALANG | C6: 5 | D6: Mustika Sari; NANDA WESTIA ADE NINGSIH; putri nasriati; Yola septya syamsi; Yulia ningsih | E6: 477.1 | F6: 1.2 | G6: Irawita | H6: 96 | I6: 3.9985986 | J6: 5 | K6: Calon PML
A7: K-03 | B7: GUNUNG TALANG | C7: 5 | D7: Ayang Syafriani; Indri septiadi; Mirvan Harvia; muhamad iqbal; Sherli Handayani * | E7: 776.2 | F7: 0.9 | G7: Inggrit yulia hastri | H7: 197 | I7: 2.3490241 | J7: 4 | K7: Calon PML
A8: K-04 | B8: JUNJUNG SIRIH | C8: 5 | D8: Alhammah Alam 'Gina *; Badrizal *; Berni desriyanti *; Julia Lara Zamzamy *; Reni Fatriani | E8: 818.1 | F8: 2.5 | G8: Leni Fatimah | H8: 430 | I8: 9.0264403 | J8: 4 | K8: Calon PML
A9: K-05 | B9: JUNJUNG SIRIH | C9: 4 | D9: Hafni Syamfitria *; Ira Wahyuni; Kodratur rahman *; ROBI ALVIAN | E9: 685.1 | F9: 0.5 | G9: Puji Putri | H9: 165 | I9: 0.45971077 | J9: 5 | K9: Calon PML
A10: K-06 | B10: JUNJUNG SIRIH | C10: 4 | D10: NIA FEBRIWENI *; Novi Endria Jhoni; Nurul vani fatia; Rini Nofsiska Sari | E10: 754.7 | F10: 0.4 | G10: usyenti | H10: 168 | I10: 0.32147349 | J10: 5 | K10: Calon PML
A11: K-07 | B11: JUNJUNG SIRIH | C11: 5 | D11: Aniza Nurzanah; Febri Handayani *; MINDA SUSANTI; NOVA ALIZA *; Weza Deftalia * | E11: 1040.4 | F11: 1.5 | G11: Budi Pernandes | H11: 159 | I11: 0.91208979 | J11: 5 | K11: Calon PML
A12: K-08 | B12: JUNJUNG SIRIH | C12: 4 | D12: Dara muhaima febriana; M. Hafizh Dinu Aulia; Rivo Nofri Armon; Wahyu Isman Asmi * | E12: 797.4 | F12: 1.4 | G12: ONDRI YANDI | H12: 396 | I12: 10.317667 | J12: 5 | K12: Calon PML
A13: K-09 | B13: KUBUNG | C13: 4 | D13: Biki Wabihamdika; Clara Amelya Hendres; PUSPITA PUTRI; Zheta Renisa Azani | E13: 728 | F13: 2.2 | G13: HANIFAH | H13: 193 | I13: 2.0383438 | J13: 4 | K13: Calon PML
A14: K-10 | B14: KUBUNG | C14: 5 | D14: ANIKE PUTRI; Defitra Yeni; Dhini oktaviani; NAILA SABATINI; nopi nofila | E14: 827.2 | F14: 1.1 | G14: MIRA ROZALINDA | H14: 205 | I14: 1.3824698 | J14: 5 | K14: Calon PML
A15: K-11 | B15: KUBUNG | C15: 5 | D15: Anggun Rahma Fajar; Elvira Okzayenti; IDORA ATIA; Nadia wati; Ranu Artysanda | E15: 679.8 | F15: 0.9 | G15: Hariston | H15: 459 | I15: 0.24438239 | K15: Calon PML | L15: Nama sama dgn pegawai organik (cek apakah orang yg sama); Belum konfirmasi bencana; Belum dinilai
A16: K-12 | B16: KUBUNG | C16: 4 | D16: Fuji erizka; Nindi Oktaviana *; Siti Oktavia *; Wirastri Widuri | E16: 512 | F16: 0.2 | G16: Widya Verawati | H16: 230 | I16: 2.9493063 | J16: 4 | K16: Calon PML | L16: Belum konfirmasi bencana
A17: K-13 | B17: KUBUNG | C17: 5 | D17: Farah Sahara; Nurpatri *; Yenni Rizka Putri; Yogi eka Putra; Yora Komala Sari | E17: 788.5 | F17: 1 | G17: Imilsi asgra varka | H17: 194 | I17: 2.4918159 | J17: 4 | K17: Calon PML
A18: K-14 | B18: KUBUNG | C18: 4 | D18: Afdhal Rezeki *; Iza Mutiarana *; Syafika Amalia *; Witri Nadia Devita Sari * | E18: 465.6 | F18: 0.1 | G18: Saputra Ebel Feri | H18: 227 | I18: 1.133961 | J18: 5 | K18: Calon PML
A19: K-15 | B19: KUBUNG | C19: 4 | D19: Asmedi Surya; Dini Fonika Putri *; Eka ramadani; Nelva Roza Oktakia | E19: 493.3 | F19: 1.5 | G19: Yurneti | H19: 241 | I19: 1.0330764 | J19: 4 | K19: Calon PML
A20: K-16 | B20: KUBUNG | C20: 5 | D20: FELIA NOVELIZA *; NILAM SITARESMI CAHYONO; Nurul Fadila Ramadhani *; Resi Linda Putri *; Sri wahyuni | E20: 582.6 | F20: 0.5 | G20: Wina Zurlaili | H20: 231 | I20: 2.3904722 | J20: 5 | K20: Calon PML
A21: K-17 | B21: LEMBAH GUMANTI | C21: 5 | D21: Elvika oktasari; Gusna Wirda; HANIFAH TURAHMI; Lara Febria Sari; Wahyuni Oktavia | E21: 717.4 | F21: 11.1 | G21: Pegawai Organik (diplot nanti) | K21: Organik | L21: Tidak ada calon PML yang tersisa dalam 15 km
A22: K-18 | B22: X KOTO SINGKARAK | C22: 4 | D22: Fikri Mardiyani; Jahar Nas; Nur Aisyah; Zahria Fitri Andini | E22: 844.7 | F22: 1.7 | G22: Indah Permata Sari | H22: 195 | I22: 7.8995721 | J22: 5 | K22: Calon PML | L22: Belum konfirmasi bencana
A23: K-19 | B23: X KOTO SINGKARAK | C23: 4 | D23: Agri renta falusia; Fahrul Ramadhani *; Filzah Asyet *; Salsa Billa Duwita Putri | E23: 756.9 | F23: 0.3 | G23: Dessy Meiyarni | H23: 422 | I23: 3.2809518 | J23: 5 | K23: Calon PML
A24: K-20 | B24: X KOTO SINGKARAK | C24: 5 | D24: Annisa Suryani; Gusma Rida *; Mira apridayanti; Sri Hati Putri; WENI DESTI * | E24: 1006.6 | F24: 0.4 | G24: ABDUL LATIF | H24: 408 | I24: 4.0761442 | J24: 4 | K24: Calon PML | L24: Belum konfirmasi bencana
A25: K-21 | B25: X KOTO SINGKARAK | C25: 4 | D25: Amelia; Bayu pratama; Debi Wulandari *; Velmarniati * | E25: 762.3 | F25: 0.8 | G25: Reza Sativa | H25: 440 | I25: 2.5656638 | J25: 4 | K25: Calon PML | L25: Belum konfirmasi bencana
A26: K-22 | B26: X KOTO SINGKARAK | C26: 4 | D26: Adri yoy marten *; desi warni *; FENNY ANDA LISTI; Sukma Yuliandra Putri * | E26: 705.9 | F26: 0.8 | G26: Rifa Amelia | H26: 441 | I26: 5.2788223 | J26: 4 | K26: Calon PML | L26: Belum konfirmasi bencana
A28: * = rekrut baru (belum dikonfirmasi). PML dari 'Calon PML' = sisa yang tidak dialihkan jadi PPL, tidak bentrok kegiatan lain, tidak red flag.

Sheet Anggota Klaster PML
A1: Anggota Klaster PML per PPL
A2: Satu baris per PPL (termasuk rekrut baru). Klaster boleh lintas kecamatan.
A4: Klaster | B4: Kecamatan | C4: Nama PPL | D4: ID | E4: Jenis | F4: Beban Saran (skor) | G4: Saran PML Klaster
A5: K-01 | B5: GUNUNG TALANG | C5: Diana Endang Pratiwi | D5: 83 | E5: PPL existing | F5: 86 | G5: Ilham
A6: K-01 | B6: GUNUNG TALANG | C6: FEBRIA RAMANITA | D6: 49 | E6: PPL existing | F6: 145.5 | G6: Ilham
A7: K-01 | B7: GUNUNG TALANG | C7: Mardiati | D7: 101 | E7: PPL existing | F7: 134.8 | G7: Ilham
A8: K-01 | B8: GUNUNG TALANG | C8: Sonya aldes fatma | D8: 122 | E8: PPL existing | F8: 127.2 | G8: Ilham
A9: K-01 | B9: GUNUNG TALANG | C9: Valina alsisri | D9: 125 | E9: PPL existing | F9: 81.8 | G9: Ilham
A10: K-02 | B10: GUNUNG TALANG | C10: Mustika Sari | D10: 106 | E10: PPL existing | F10: 69.7 | G10: Irawita
A11: K-02 | B11: GUNUNG TALANG | C11: NANDA WESTIA ADE NINGSIH | D11: 108 | E11: PPL existing | F11: 85.5 | G11: Irawita
A12: K-02 | B12: GUNUNG TALANG | C12: putri nasriati | D12: 117 | E12: PPL existing | F12: 78.8 | G12: Irawita
A13: K-02 | B13: GUNUNG TALANG | C13: Yola septya syamsi | D13: 127 | E13: PPL existing | F13: 159.7 | G13: Irawita
A14: K-02 | B14: GUNUNG TALANG | C14: Yulia ningsih | D14: 129 | E14: PPL existing | F14: 83.4 | G14: Irawita
A15: K-03 | B15: GUNUNG TALANG | C15: Ayang Syafriani | D15: 74 | E15: PPL existing | F15: 146.1 | G15: Inggrit yulia hastri
A16: K-03 | B16: GUNUNG TALANG | C16: Indri septiadi | D16: 94 | E16: PPL existing | F16: 150.3 | G16: Inggrit yulia hastri
... A103: K-22 | B103: X KOTO SINGKARAK | C103: Sukma Yuliandra Putri | D103: 330 | E103: Rekrut baru | F103: 216.7 | G103: Rifa Amelia

Sheet Existing vs Saran
A1: Existing vs Saran Plotting PPL per Sub SLS (versi 2)
A2: Hanya SARAN - plotting yang tersimpan di sistem TIDAK diubah. Sub SLS berskor sangat besar dipecah jadi beberapa porsi (kolom Porsi).
A4: ID Sub SLS | B4: Kecamatan | C4: Nagari | D4: SLS | E4: Sub SLS | F4: Jumlah KK | G4: Skor Beban Wilayah (penuh) | H4: Porsi | I4: Skor Beban Unit Ini | J4: ID PPL Existing | K4: PPL Existing | L4: Beban Wilayah Existing (skor) | M4: Jarak Existing (km) | N4: ID PPL Saran | O4: PPL Saran | P4: Sumber PPL Saran | Q4: Jarak Saran (km) | R4: Skor Beban PPL Saran (total) | S4: Jenis Perubahan | T4: Catatan
A5: 1303071002000101 | B5: DANAU KEMBAR | C5: SIMPANG TANJUANG NAN IV | D5: JORONG KAPALO DANAU BAWAH | E5: 01 | F5: 136 | G5: 21.09 | H5: 1/1 | I5: =ROUND(G5/1,2) -> 21.09 | J5: 49 | K5: FEBRIA RAMANITA | L5: =G5 -> 21.09 | M5: 1.28 | N5: 49 | O5: FEBRIA RAMANITA | P5: PPL existing | Q5: 1.2779978 | R5: =IF(N5="","",SUMIFS($I$5:$I$210,$N$5:$N$210,N5)) -> 145.52 | S5: Tetap (pertahankan)
A6: 1303071002000201 | B6: DANAU KEMBAR | C6: SIMPANG TANJUANG NAN IV | D6: JORONG KAPALO DANAU ATEH | E6: 01 | F6: 205 | G6: 35.52 | H6: 1/1 | I6: =ROUND(G6/1,2) -> 35.52 | J6: 49 | K6: FEBRIA RAMANITA | L6: =G6 -> 35.52 | M6: 0.76 | N6: 49 | O6: FEBRIA RAMANITA | P6: PPL existing | Q6: 0.75853287 | R6: =IF(N6="","",SUMIFS($I$5:$I$210,$N$5:$N$210,N6)) -> 145.52 | S6: Tetap (pertahankan)
A7: 1303071002000700 | B7: DANAU KEMBAR | C7: SIMPANG TANJUANG NAN IV | D7: JORONG TALUAK KINARI | E7: 00 | F7: 208 | G7: 34.29 | H7: 1/1 | I7: =ROUND(G7/1,2) -> 34.29 | J7: 49 | K7: FEBRIA RAMANITA | L7: =G7 -> 34.29 | M7: 3.78 | N7: 49 | O7: FEBRIA RAMANITA | P7: PPL existing | Q7: 3.7760351 | R7: =IF(N7="","",SUMIFS($I$5:$I$210,$N$5:$N$210,N7)) -> 145.52 | S7: Tetap (pertahankan)
A8: 1303071002000802 | B8: DANAU KEMBAR | C8: SIMPANG TANJUANG NAN IV | D8: JORONG TALUAK ANJALAI | E8: 02 | F8: 194 | G8: 30.8 | H8: 1/1 | I8: =ROUND(G8/1,2) -> 30.8 | J8: 49 | K8: FEBRIA RAMANITA | L8: =G8 -> 30.8 | M8: 4.84 | N8: 49 | O8: FEBRIA RAMANITA | P8: PPL existing | Q8: 4.843593 | R8: =IF(N8="","",SUMIFS($I$5:$I$210,$N$5:$N$210,N8)) -> 145.52 | S8: Tetap (pertahankan)
A9: 1303071002000901 | B9: DANAU KEMBAR | C9: SIMPANG TANJUANG NAN IV | D9: JORONG RAWANG GADANG | E9: 01 | F9: 156 | G9: 23.82 | H9: 1/1 | I9: =ROUND(G9/1,2) -> 23.82 | J9: 65 | K9: Weza Deftalia | L9: =G9 -> 23.82 | M9: 3.86 | N9: 49 | O9: FEBRIA RAMANITA | P9: PPL existing | Q9: 4.7232696 | R9: =IF(N9="","",SUMIFS($I$5:$I$210,$N$5:$N$210,N9)) -> 145.52 | S9: Gabung (beban PPL terlalu kecil) | T9: Beban Weza Deftalia terlalu kecil (23.8) -> digabung ke FEBRIA RAMANITA (total 145.5); jarak maks 4.7 km
A10: 1303080008000401 | B10: GUNUNG TALANG | C10: AIE BATUMBUAK | D10: JORONG KOTO BARUAH | E10: 01 | F10: 127 | G10: 27.47 | H10: 1/1 | I10: =ROUND(G10/1,2) -> 27.47 | J10: 99 | K10: Julia Lara Zamzamy | L10: =G10 -> 27.47 | M10: 0.21 | N10: 122 | O10: Sonya aldes fatma | P10: PPL existing | Q10: 7.7666926 | R10: =IF(N10="","",SUMIFS($I$5:$I$210,$N$5:$N$210,N10)) -> 127.15 | S10: Gabung (beban PPL terlalu kecil) | T10: Beban Julia Lara Zamzamy terlalu kecil (27.5) -> digabung ke Sonya aldes fatma (total 127.2); jarak maks 7.8 km [perluasan radius] [perluasan radius]
A11: 1303080007000104 | B11: GUNUNG TALANG | C11: BATANG BARUS | D11: JORONG KAYU ARO | E11: 04 | F11: 158 | G11: 86.03 | H11: 1/1 | I11: =ROUND(G11/1,2) -> 86.03 | J11: 83 | K11: Diana Endang Pratiwi | L11: =G11 -> 86.03 | M11: 1.27 | N11: 83 | O11: Diana Endang Pratiwi | P11: PPL existing | Q11: 1.27144 | R11: =IF(N11="","",SUMIFS($I$5:$I$210,$N$5:$N$210,N11)) -> 86.03 | S11: Tetap (pertahankan)
A12: 1303080007000108 | B12: GUNUNG TALANG | C12: BATANG BARUS | D12: JORONG KAYU ARO | E12: 08 | F12: 112 | G12: 78.82 | H12: 1/1 | I12: =ROUND(G12/1,2) -> 78.82 | J12: 117 | K12: putri nasriati | L12: =G12 -> 78.82 | M12: 0.63 | N12: 117 | O12: putri nasriati | P12: PPL existing | Q12: 0.6291584 | R12: =IF(N12="","",SUMIFS($I$5:$I$210,$N$5:$N$210,N12)) -> 78.82 | S12: Tetap (pertahankan)
A13: 1303080007000109 | B13: GUNUNG TALANG | C13: BATANG BARUS | D13: JORONG KAYU ARO | E13: 09 | F13: 142 | G13: 85.5 | H13: 1/1 | I13: =ROUND(G13/1,2) -> 85.5 | J13: 108 | K13: NANDA WESTIA ADE NINGSIH | L13: =G13 -> 85.5 | M13: 3.02 | N13: 108 | O13: NANDA WESTIA ADE NINGSIH | P13: PPL existing | Q13: 3.0159078 | R13: =IF(N13="","",SUMIFS($I$5:$I$210,$N$5:$N$210,N13)) -> 85.5 | S13: Tetap (pertahankan)
A14: 1303080007000111 | B14: GUNUNG TALANG | C14: BATANG BARUS | D14: JORONG KAYU ARO | E14: 11 | F14: 137 | G14: 83.39 | H14: 1/1 | I14: =ROUND(G14/1,2) -> 83.39 | J14: 129 | K14: Yulia ningsih | L14: =G14 -> 83.39 | M14: 1.63 | N14: 129 | O14: Yulia ningsih | P14: PPL existing | Q14: 1.6317509 | R14: =IF(N14="","",SUMIFS($I$5:$I$210,$N$5:$N$210,N14)) -> 83.39 | S14: Tetap (pertahankan)
A15: 1303080007000201 | B15: GUNUNG TALANG | C15: BATANG BARUS | D15: JORONG LUBUK SELASIH | E15: 01 | F15: 177 | G15: 27.07 | H15: 1/1 | I15: =ROUND(G15/1,2) -> 27.07 | J15: 122 | K15: Sonya aldes fatma | L15: =G15 -> 27.07 | M15: 1.61 | N15: 122 | O15: Sonya aldes fatma | P15: PPL existing | Q15: 1.6108204 | R15: =IF(N15="","",SUMIFS($I$5:$I$210,$N$5:$N$210,N15)) -> 127.15 | S15: Tetap (pertahankan)
A16: 1303080007000202 | B16: GUNUNG TALANG | C16: BATANG BARUS | D16: JORONG LUBUK SELASIH | E16: 02 | F16: 178 | G16: 48.76 | H16: 1/1 | I16: =ROUND(G16/1,2) -> 48.76 | J16: 122 | K16: Sonya aldes fatma | L16: =G16 -> 48.76 | M16: 0.33 | N16: 122 | O16: Sonya aldes fatma | P16: PPL existing | Q16: 0.33368184 | R16: =IF(N16="","",SUMIFS($I$5:$I$210,$N$5:$N$210,N16)) -> 127.15 | S16: Tetap (pertahankan)
A17: 1303080007000204 | B17: GUNUNG TALANG | C17: BATANG BARUS | D17: JORONG LUBUK SELASIH | E17: 04 | F17: 147 | G17: 23.85 | H17: 1/1 | I17: =ROUND(G17/1,2) -> 23.85 | J17: 122 | K17: Sonya aldes fatma | L17: =G17 -> 23.85 | M17: 1.35 | N17: 122 | O17: Sonya aldes fatma | P17: PPL existing | Q17: 1.3487011 | R17: =IF(N17="","",SUMIFS($I$5:$I$210,$N$5:$N$210,N17)) -> 127.15 | S17: Tetap (pertahankan)
A18: 1303080001000106 | B18: GUNUNG TALANG | C18: CUPAK | D18: JORONG SUNGAI ROTAN | E18: 06 | F18: 170 | G18: 28.09 | H18: 1/1 | I18: =ROUND(G18/1,2) -> 28.09 | J18: 107 | K18: NAILA SABATINI | L18: =G18 -> 28.09 | M18: 0.85 | N18: 107 | O18: NAILA SABATINI | P18: PPL existing | Q18: 0.85148892 | R18: =IF(N18="","",SUMIFS($I$5:$I$210,$N$5:$N$210,N18)) -> 214.82 | S18: Tetap (pertahankan)
A19: 1303080001000801 | B19: GUNUNG TALANG | C19: CUPAK | D19: JORONG SAWAH TALUAK | E19: 01 | F19: 114 | G19: 16.88 | H19: 1/1 | I19: =ROUND(G19/1,2) -> 16.88 | J19: 107 | K19: NAILA SABATINI | L19: =G19 -> 16.88 | M19: 1.49 | N19: 107 | O19: NAILA SABATINI | P19: PPL existing | Q19: 1.4863518 | R19: =IF(N19="","",SUMIFS($I$5:$I$210,$N$5:$N$210,N19)) -> 214.82 | S19: Tetap (pertahankan)
A20: 1303080001000802 | B20: GUNUNG TALANG | C20: CUPAK | D20: JORONG SAWAH TALUAK | E20: 02 | F20: 129 | G20: 19.13 | H20: 1/1 | I20: =ROUND(G20/1,2) -> 19.13 | J20: 181 | K20: Defitra Yeni | L20: =G20 -> 19.13 | M20: 1.78 | N20: 181 | O20: Defitra Yeni | P20: PPL existing | Q20: 1.778494 | R20: =IF(N20="","",SUMIFS($I$5:$I$210,$N$5:$N$210,N20)) -> 144.3 | S20: Tetap (pertahankan)
A21: 1303080001000804 | B21: GUNUNG TALANG | C21: CUPAK | D21: JORONG SAWAH TALUAK | E21: 04 | F21: 180 | G21: 26.18 | H21: 1/1 | I21: =ROUND(G21/1,2) -> 26.18 | J21: 82 | K21: Dhini oktaviani | L21: =G21 -> 26.18 | M21: 1.19 | N21: 82 | O21: Dhini oktaviani | P21: PPL existing | Q21: 1.1930319 | R21: =IF(N21="","",SUMIFS($I$5:$I$210,$N$5:$N$210,N21)) -> 185.32 | S21: Tetap (pertahankan)
A22: 1303080001000901 | B22: GUNUNG TALANG | C22: CUPAK | D22: JORONG TANGAH PADANG | E22: 01 | F22: 166 | G22: 24.64 | H22: 1/1 | I22: =ROUND(G22/1,2) -> 24.64 | J22: 78 | K22: Clara Amelya Hendres | L22: =G22 -> 24.64 | M22: 2.36 | N22: 78 | O22: Clara Amelya Hendres | P22: PPL existing | Q22: 2.3581267 | R22: =IF(N22="","",SUMIFS($I$5:$I$210,$N$5:$N$210,N22)) -> 204.54 | S22: Tetap (pertahankan)
A23: 1303080001000902 | B23: GUNUNG TALANG | C23: CUPAK | D23: JORONG TANGAH PADANG | E23: 02 | F23: 168 | G23: 24.67 | H23: 1/1 | I23: =ROUND(G23/1,2) -> 24.67 | J23: 107 | K23: NAILA SABATINI | L23: =G23 -> 24.67 | M23: 1.7 | N23: 107 | O23: NAILA SABATINI | P23: PPL existing | Q23: 1.6968043 | R23: =IF(N23="","",SUMIFS($I$5:$I$210,$N$5:$N$210,N23)) -> 214.82 | S23: Tetap (pertahankan)
A24: 1303080004000402 | B24: GUNUNG TALANG | C24: KOTO GADANG GUGUAK | D24: JORONG PASAR USANG | E24: 02 | F24: 159 | G24: 23.33 | H24: 1/1 | I24: =ROUND(G24/1,2) -> 23.33 | J24: 77 | K24: Berni desriyanti | L24: =G24 -> 23.33 | M24: 1.56 | N24: 127 | O24: Yola septya syamsi | P24: PPL existing | Q24: 1.9653207 | R24: =IF(N24="","",SUMIFS($I$5:$I$210,$N$5:$N$210,N24)) -> 159.7 | S24: Gabung (beban PPL terlalu kecil) | T24: Beban Berni desriyanti terlalu kecil (23.3) -> digabung ke Yola septya syamsi (total 159.7); jarak maks 2.0 km
A25: 1303080004000602 | B25: GUNUNG TALANG | C25: KOTO GADANG GUGUAK | D25: JORONG TALAGO | E25: 02 | F25: 113 | G25: 16.21 | H25: 1/1 | I25: =ROUND(G25/1,2) -> 16.21 | J25: 101 | K25: Mardiati | L25: =G25 -> 16.21 | M25: 0.17 | N25: 101 | O25: Mardiati | P25: PPL existing | Q25: 0.17015724 | R25: =IF(N25="","",SUMIFS($I$5:$I$210,$N$5:$N$210,N25)) -> 134.8 | S25: Tetap (pertahankan)
A26: 1303080004000702 | B26: GUNUNG TALANG | C26: KOTO GADANG GUGUAK | D26: JORONG BUKIK GOMPONG | E26: 02 | F26: 151 | G26: 81.8 | H26: 1/1 | I26: =ROUND(G26/1,2) -> 81.8 | J26: 125 | K26: Valina alsisri | L26: =G26 -> 81.8 | M26: 0.06 | N26: 125 | O26: Valina alsisri | P26: PPL existing | Q26: 0.057387969 | R26: =IF(N26="","",SUMIFS($I$5:$I$210,$N$5:$N$210,N26)) -> 81.8 | S26: Tetap (pertahankan)
A27: 1303080005000201 | B27: GUNUNG TALANG | C27: KOTO GAEK GUGUK | D27: JORONG SUKARAMI | E27: 01 | F27: 206 | G27: 69.68 | H27: 1/1 | I27: =ROUND(G27/1,2) -> 69.68 | J27: 106 | K27: Mustika Sari | L27: =G27 -> 69.68 | M27: 2.89 | N27: 106 | O27: Mustika Sari | P27: PPL existing | Q27: 2.891407 | R27: =IF(N27="","",SUMIFS($I$5:$I$210,$N$5:$N$210,N27)) -> 69.68 | S27: Tetap (pertahankan)
A28: 1303080005000202 | B28: GUNUNG TALANG | C28: KOTO GAEK GUGUK | D28: JORONG SUKARAMI | E28: 02 | F28: 207 | G28: 69.1 | H28: 1/1 | I28: =ROUND(G28/1,2) -> 69.1 | J28: 127 | K28: Yola septya syamsi | L28: =G28 -> 69.1 | M28: 1.98 | N28: 127 | O28: Yola septya syamsi | P28: PPL existing | Q28: 1.9782271 | R28: =IF(N28="","",SUMIFS($I$5:$I$210,$N$5:$N$210,N28)) -> 159.7 | S28: Tetap (pertahankan)
A29: 1303080005000203 | B29: GUNUNG TALANG | C29: KOTO GAEK GUGUK | D29: JORONG SUKARAMI | E29: 03 | F29: 128 | G29: 57.72 | H29: 1/1 | I29: =ROUND(G29/1,2) -> 57.72 | J29: 101 | K29: Mardiati | L29: =G29 -> 57.72 | M29: 1.86 | N29: 101 | O29: Mardiati | P29: PPL existing | Q29: 1.8614532 | R29: =IF(N29="","",SUMIFS($I$5:$I$210,$N$5:$N$210,N29)) -> 134.8 | S29: Tetap (pertahankan)
A30: 1303080005000204 | B30: GUNUNG TALANG | C30: KOTO GAEK GUGUK | D30: JORONG SUKARAMI | E30: 04 | F30: 156 | G30: 60.87 | H30: 1/1 | I30: =ROUND(G30/1,2) -> 60.87 | J30: 101 | K30: Mardiati | L30: =G30 -> 60.87 | M30: 0.8 | N30: 101 | O30: Mardiati | P30: PPL existing | Q30: 0.79756017 | R30: =IF(N30="","",SUMIFS($I$5:$I$210,$N$5:$N$210,N30)) -> 134.8 | S30: Tetap (pertahankan)
A31: 1303080005000205 | B31: GUNUNG TALANG | C31: KOTO GAEK GUGUK | D31: JORONG SUKARAMI | E31: 05 | F31: 195 | G31: 67.27 | H31: 1/1 | I31: =ROUND(G31/1,2) -> 67.27 | J31: 127 | K31: Yola septya syamsi | L31: =G31 -> 67.27 | M31: 1.84 | N31: 127 | O31: Yola septya syamsi | P31: PPL existing | Q31: 1.840292 | R31: =IF(N31="","",SUMIFS($I$5:$I$210,$N$5:$N$210,N31)) -> 159.7 | S31: Tetap (pertahankan)
A32: 1303080002000501 | B32: GUNUNG TALANG | C32: TALANG | D32: JORONG KOTO GADANG | E32: 01 | F32: 119 | G32: 17.75 | H32: 1/1 | I32: =ROUND(G32/1,2) -> 17.75 | J32: 111 | K32: nopi nofila | L32: =G32 -> 17.75 | M32: 1.91 | N32: 111 | O32: nopi nofila | P32: PPL existing | Q32: 1.9141889 | R32: =IF(N32="","",SUMIFS($I$5:$I$210,$N$5:$N$210,N32)) -> 145.99 | S32: Tetap (pertahankan)
A33: 1303080002000502 | B33: GUNUNG TALANG | C33: TALANG | D33: JORONG KOTO GADANG | E33: 02 | F33: 129 | G33: 18.98 | H33: 1/1 | I33: =ROUND(G33/1,2) -> 18.98 | J33: 102 | K33: Mirvan Harvia | L33: =G33 -> 18.98 | M33: 1.4 | N33: 102 | O33: Mirvan Harvia | P33: PPL existing | Q33: 1.4003182 | R33: =IF(N33="","",SUMIFS($I$5:$I$210,$N$5:$N$210,N33)) -> 146.55 | S33: Tetap (pertahankan)
A34: 1303080002000503 | B34: GUNUNG TALANG | C34: TALANG | D34: JORONG KOTO GADANG | E34: 03 | F34: 127 | G34: 18.64 | H34: 1/1 | I34: =ROUND(G34/1,2) -> 18.64 | J34: 74 | K34: Ayang Syafriani | L34: =G34 -> 18.64 | M34: 1.26 | N34: 74 | O34: Ayang Syafriani | P34: PPL existing | Q34: 1.2569748 | R34: =IF(N34="","",SUMIFS($I$5:$I$210,$N$5:$N$210,N34)) -> 146.14 | S34: Tetap (pertahankan)
A35: 1303080002000504 | B35: GUNUNG TALANG | C35: TALANG | D35: JORONG KOTO GADANG | E35: 04 | F35: 154 | G35: 22.51 | H35: 1/1 | I35: =ROUND(G35/1,2) -> 22.51 | J35: 94 | K35: Indri septiadi | L35: =G35 -> 22.51 | M35: 1.31 | N35: 94 | O35: Indri septiadi | P35: PPL existing | Q35: 1.3108044 | R35: =IF(N35="","",SUMIFS($I$5:$I$210,$N$5:$N$210,N35)) -> 150.28 | S35: Tetap (pertahankan)
A36: 1303140001000100 | B36: JUNJUNG SIRIH | C36: MUARO PINGAI | D36: JORONG KOTO | E36: 00 | F36: 218 | G36: 229.48 | H36: 1/2 | I36: =ROUND(G36/2,2) -> 114.74 | J36: 390 | K36: FENNY ANDA LISTI | L36: =G36 -> 229.48 | M36: 11.26 | N36: 390 | O36: FENNY ANDA LISTI | P36: PPL existing | Q36: 11.260293 | R36: =IF(N36="","",SUMIFS($I$5:$I$210,$N$5:$N$210,N36)) -> 213.44 | S36: Tetap (pertahankan) | T36: Tidak ada kandidat yg jauh lebih dekat/longgar dalam radius -- dipertahankan
A37: 1303140001000100 | B37: JUNJUNG SIRIH | C37: MUARO PINGAI | D37: JORONG KOTO | E37: 00 | F37: 218 | G37: 229.48 | H37: 2/2 | I37: =ROUND(G37/2,2) -> 114.74 | N37: 276 | O37: Kodratur rahman | P37: Rekrut baru | Q37: 64.052819 | R37: =IF(N37="","",SUMIFS($I$5:$I$210,$N$5:$N$210,N37)) -> 114.74 | S37: Bagi porsi (Sub SLS berat) | T37: Tidak ada kandidat existing/pool yg memenuhi radius & batas beban -> disarankan rekrut baru (lihat sheet Kebutuhan PPL Tambahan)
A38: 1303140001000201 | B38: JUNJUNG SIRIH | C38: MUARO PINGAI | D38: JORONG GUCI IV | E38: 01 | F38: 121 | G38: 139.45 | H38: 1/1 | I38: =ROUND(G38/1,2) -> 139.45 | J38: 426 | K38: Ira Wahyuni | L38: =G38 -> 139.45 | M38: 4.61 | N38: 426 | O38: Ira Wahyuni | P38: PPL existing | Q38: 4.6101183 | R38: =IF(N38="","",SUMIFS($I$5:$I$210,$N$5:$N$210,N38)) -> 214.08 | S38: Tetap (pertahankan)
A39: 1303140001000202 | B39: JUNJUNG SIRIH | C39: MUARO PINGAI | D39: JORONG GUCI IV | E39: 02 | F39: 124 | G39: 151.25 | H39: 1/1 | I39: =ROUND(G39/1,2) -> 151.25 | J39: 394 | K39: Mira apridayanti | L39: =G39 -> 151.25 | M39: 12.73 | N39: 439 | O39: Nurul vani fatia | P39: Pool (baru diplot) | Q39: 6.6085507 | R39: =IF(N39="","",SUMIFS($I$5:$I$210,$N$5:$N$210,N39)) -> 214.67 | S39: Relokasi - jarak jauh | T39: jarak 6.6 km
A40: 1303140001000300 | B40: JUNJUNG SIRIH | C40: MUARO PINGAI | D40: JORONG GUCI II | E40: 00 | F40: 177 | G40: 429.67 | H40: 1/3 | I40: =ROUND(G40/3,2) -> 143.22 | J40: 420 | K40: Dara muhaima febriana | L40: =G40 -> 429.67 | M40: 6.35 | N40: 420 | O40: Dara muhaima febriana | P40: PPL existing | Q40: 6.345646 | R40: =IF(N40="","",SUMIFS($I$5:$I$210,$N$5:$N$210,N40)) -> 198.94 | S40: Tetap (pertahankan)
A41: 1303140001000300 | B41: JUNJUNG SIRIH | C41: MUARO PINGAI | D41: JORONG GUCI II | E41: 00 | F41: 177 | G41: 429.67 | H41: 2/3 | I41: =ROUND(G41/3,2) -> 143.22 | N41: 380 | O41: Wahyu Isman Asmi | P41: Rekrut baru | Q41: 78.891106 | R41: =IF(N41="","",SUMIFS($I$5:$I$210,$N$5:$N$210,N41)) -> 213.04 | S41: Bagi porsi (Sub SLS berat) | T41: Tidak ada kandidat existing/pool yg memenuhi radius & batas beban -> disarankan rekrut baru (lihat sheet Kebutuhan PPL Tambahan)
...

Sheet Beban per PPL
A1: Beban per PPL: Existing vs Saran
A2: Beban dihitung ulang otomatis (rumus) dari sheet Existing vs Saran. Batas berlebih & ideal mengacu ke sheet Parameter & Asumsi.
A4: ID | B4: Nama PPL | C4: Sumber / Peran | D4: Nilai Kinerja | E4: Kecamatan Domisili | F4: Sub SLS Existing | G4: Beban Existing (skor) | H4: Sub SLS Saran (unit) | I4: Beban Saran (skor) | J4: Selisih Beban | K4: Status Beban Saran | L4: Catatan
A5: 22 | B5: Elvira Okzayenti | C5: PPL existing | D5: 5 | E5: BUKIT SUNDI | F5: =COUNTIFS('Existing vs Saran'!$J$5:$J$210,A5) -> 2 | G5: =SUMIFS('Existing vs Saran'!$L$5:$L$210,'Existing vs Saran'!$J$5:$J$210,A5) -> 346.44 | H5: =COUNTIFS('Existing vs Saran'!$N$5:$N$210,A5) -> 1 | I5: =SUMIFS('Existing vs Saran'!$I$5:$I$210,'Existing vs Saran'!$N$5:$N$210,A5) -> 105.26 | J5: =I5-G5 -> -241.18 | K5: =IF(I5=0,"Tidak dipakai",IF(I5>'Parameter & Asumsi'!$B$8,"Berlebih",IF(I5<100,"Ringan","Wajar"))) -> Wajar
A6: 27 | B6: muhamad iqbal | C6: PPL existing | D6: 5 | E6: BUKIT SUNDI | F6: =COUNTIFS('Existing vs Saran'!$J$5:$J$210,A6) -> 2 | G6: =SUMIFS('Existing vs Saran'!$L$5:$L$210,'Existing vs Saran'!$J$5:$J$210,A6) -> 240.11 | H6: =COUNTIFS('Existing vs Saran'!$N$5:$N$210,A6) -> 2 | I6: =SUMIFS('Existing vs Saran'!$I$5:$I$210,'Existing vs Saran'!$N$5:$N$210,A6) -> 213.61 | J6: =I6-G6 -> -26.5 | K6: =IF(I6=0,"Tidak dipakai",IF(I6>'Parameter & Asumsi'!$B$8,"Berlebih",IF(I6<100,"Ringan","Wajar"))) -> Wajar
A7: 31 | B7: Nadia wati | C7: PPL existing | D7: 5 | E7: BUKIT SUNDI | F7: =COUNTIFS('Existing vs Saran'!$J$5:$J$210,A7) -> 3 | G7: =SUMIFS('Existing vs Saran'!$L$5:$L$210,'Existing vs Saran'!$J$5:$J$210,A7) -> 226.43 | H7: =COUNTIFS('Existing vs Saran'!$N$5:$N$210,A7) -> 2 | I7: =SUMIFS('Existing vs Saran'!$I$5:$I$210,'Existing vs Saran'!$N$5:$N$210,A7) -> 124.26 | J7: =I7-G7 -> -102.17 | K7: =IF(I7=0,"Tidak dipakai",IF(I7>'Parameter & Asumsi'!$B$8,"Berlebih",IF(I7<100,"Ringan","Wajar"))) -> Wajar
A8: 44 | B8: Badrizal | C8: Rekrut baru | D8: 5 | E8: DANAU KEMBAR | F8: =COUNTIFS('Existing vs Saran'!$J$5:$J$210,A8) -> 0 | G8: =SUMIFS('Existing vs Saran'!$L$5:$L$210,'Existing vs Saran'!$J$5:$J$210,A8) -> 0 | H8: =COUNTIFS('Existing vs Saran'!$N$5:$N$210,A8) -> 1 | I8: =SUMIFS('Existing vs Saran'!$I$5:$I$210,'Existing vs Saran'!$N$5:$N$210,A8) -> 155.97 | J8: =I8-G8 -> 155.97 | K8: =IF(I8=0,"Tidak dipakai",IF(I8>'Parameter & Asumsi'!$B$8,"Berlebih",IF(I8<100,"Ringan","Wajar"))) -> Wajar | L8: Rekrut skema MENGINAP: sudah daftar tapi belum diplot; tawarkan menginap di kontrakan PANINGGAHAN (Kec. JUNJUNG SIRIH)
A9: 49 | B9: FEBRIA RAMANITA | C9: PPL existing | D9: 4 | E9: DANAU KEMBAR | F9: =COUNTIFS('Existing vs Saran'!$J$5:$J$210,A9) -> 4 | G9: =SUMIFS('Existing vs Saran'!$L$5:$L$210,'Existing vs Saran'!$J$5:$J$210,A9) -> 121.7 | H9: =COUNTIFS('Existing vs Saran'!$N$5:$N$210,A9) -> 5 | I9: =SUMIFS('Existing vs Saran'!$I$5:$I$210,'Existing vs Saran'!$N$5:$N$210,A9) -> 145.52 | J9: =I9-G9 -> 23.82 | K9: =IF(I9=0,"Tidak dipakai",IF(I9>'Parameter & Asumsi'!$B$8,"Berlebih",IF(I9<100,"Ringan","Wajar"))) -> Wajar | L9: Memegang wilayah gabungan dari: Weza Deftalia
A10: 60 | B10: Sherli Handayani | C10: Rekrut baru | D10: 5 | E10: DANAU KEMBAR | F10: =COUNTIFS('Existing vs Saran'!$J$5:$J$210,A10) -> 0 | G10: =SUMIFS('Existing vs Saran'!$L$5:$L$210,'Existing vs Saran'!$J$5:$J$210,A10) -> 0 | H10: =COUNTIFS('Existing vs Saran'!$N$5:$N$210,A10) -> 1 | I10: =SUMIFS('Existing vs Saran'!$I$5:$I$210,'Existing vs Saran'!$N$5:$N$210,A10) -> 119.67 | J10: =I10-G10 -> 119.67 | K10: =IF(I10=0,"Tidak dipakai",IF(I10>'Parameter & Asumsi'!$B$8,"Berlebih",IF(I10<100,"Ringan","Wajar"))) -> Wajar | L10: Rekrut skema MENGINAP: sudah daftar tapi belum diplot; tawarkan menginap di kontrakan SELAYO (Kec. KUBUNG)
A11: 65 | B11: Weza Deftalia | C11: Rekrut baru | D11: 4 | E11: DANAU KEMBAR | F11: =COUNTIFS('Existing vs Saran'!$J$5:$J$210,A11) -> 1 | G11: =SUMIFS('Existing vs Saran'!$L$5:$L$210,'Existing vs Saran'!$J$5:$J$210,A11) -> 23.82 | H11: =COUNTIFS('Existing vs Saran'!$N$5:$N$210,A11) -> 2 | I11: =SUMIFS('Existing vs Saran'!$I$5:$I$210,'Existing vs Saran'!$N$5:$N$210,A11) -> 218.55 | J11: =I11-G11 -> 194.73 | K11: =IF(I11=0,"Tidak dipakai",IF(I11>'Parameter & Asumsi'!$B$8,"Berlebih",IF(I11<100,"Ringan","Wajar"))) -> Wajar | L11: Rekrut skema MENGINAP: sudah daftar tapi belum diplot; tawarkan menginap di kontrakan PANINGGAHAN (Kec. JUNJUNG SIRIH); Dilepas: beban terlalu kecil (< 60) -> wilayah digabung ke FEBRIA RAMANITA
A12: 74 | B12: Ayang Syafriani | C12: PPL existing | D12: 5 | E12: GUNUNG TALANG | F12: =COUNTIFS('Existing vs Saran'!$J$5:$J$210,A12) -> 2 | G12: =SUMIFS('Existing vs Saran'!$L$5:$L$210,'Existing vs Saran'!$J$5:$J$210,A12) -> 273.63 | H12: =COUNTIFS('Existing vs Saran'!$N$5:$N$210,A12) -> 2 | I12: =SUMIFS('Existing vs Saran'!$I$5:$I$210,'Existing vs Saran'!$N$5:$N$210,A12) -> 146.14 | J12: =I12-G12 -> -127.49 | K12: =IF(I12=0,"Tidak dipakai",IF(I12>'Parameter & Asumsi'!$B$8,"Berlebih",IF(I12<100,"Ringan","Wajar"))) -> Wajar
A13: 77 | B13: Berni desriyanti | C13: Rekrut baru | D13: 5 | E13: GUNUNG TALANG | F13: =COUNTIFS('Existing vs Saran'!$J$5:$J$210,A13) -> 1 | G13: =SUMIFS('Existing vs Saran'!$L$5:$L$210,'Existing vs Saran'!$J$5:$J$210,A13) -> 23.33 | H13: =COUNTIFS('Existing vs Saran'!$N$5:$N$210,A13) -> 1 | I13: =SUMIFS('Existing vs Saran'!$I$5:$I$210,'Existing vs Saran'!$N$5:$N$210,A13) -> 98.11 | J13: =I13-G13 -> 74.78 | K13: =IF(I13=0,"Tidak dipakai",IF(I13>'Parameter & Asumsi'!$B$8,"Berlebih",IF(I13<100,"Ringan","Wajar"))) -> Ringan | L13: Rekrut skema MENGINAP: sudah daftar tapi belum diplot; tawarkan menginap di kontrakan SANIANG BAKA (Kec. X KOTO SINGKARAK); Dilepas: beban terlalu kecil (< 60) -> wilayah digabung ke Yola septya syamsi
A14: 78 | B14: Clara Amelya Hendres | C14: PPL existing | D14: 5 | E14: GUNUNG TALANG | F14: =COUNTIFS('Existing vs Saran'!$J$5:$J$210,A14) -> 3 | G14: =SUMIFS('Existing vs Saran'!$L$5:$L$210,'Existing vs Saran'!$J$5:$J$210,A14) -> 515.77 | H14: =COUNTIFS('Existing vs Saran'!$N$5:$N$210,A14) -> 3 | I14: =SUMIFS('Existing vs Saran'!$I$5:$I$210,'Existing vs Saran'!$N$5:$N$210,A14) -> 204.54 | J14: =I14-G14 -> -311.23 | K14: =IF(I14=0,"Tidak dipakai",IF(I14>'Parameter & Asumsi'!$B$8,"Berlebih",IF(I14<100,"Ringan","Wajar"))) -> Wajar
A15: 82 | B15: Dhini oktaviani | C15: PPL existing | D15: 4 | E15: GUNUNG TALANG | F15: =COUNTIFS('Existing vs Saran'!$J$5:$J$210,A15) -> 5 | G15: =SUMIFS('Existing vs Saran'!$L$5:$L$210,'Existing vs Saran'!$J$5:$J$210,A15) -> 185.32 | H15: =COUNTIFS('Existing vs Saran'!$N$5:$N$210,A15) -> 5 | I15: =SUMIFS('Existing vs Saran'!$I$5:$I$210,'Existing vs Saran'!$N$5:$N$210,A15) -> 185.32 | J15: =I15-G15 -> 0 | K15: =IF(I15=0,"Tidak dipakai",IF(I15>'Parameter & Asumsi'!$B$8,"Berlebih",IF(I15<100,"Ringan","Wajar"))) -> Wajar
A16: 83 | B16: Diana Endang Pratiwi | C16: PPL existing | D16: 4 | E16: GUNUNG TALANG | F16: =COUNTIFS('Existing vs Saran'!$J$5:$J$210,A16) -> 1 | G16: =SUMIFS('Existing vs Saran'!$L$5:$L$210,'Existing vs Saran'!$J$5:$J$210,A16) -> 86.03 | H16: =COUNTIFS('Existing vs Saran'!$N$5:$N$210,A16) -> 1 | I16: =SUMIFS('Existing vs Saran'!$I$5:$I$210,'Existing vs Saran'!$N$5:$N$210,A16) -> 86.03 | J16: =I16-G16 -> 0 | K16: =IF(I16=0,"Tidak dipakai",IF(I16>'Parameter & Asumsi'!$B$8,"Berlebih",IF(I16<100,"Ringan","Wajar"))) -> Ringan
A17: 94 | B17: Indri septiadi | C17: PPL existing | D17: 5 | E17: GUNUNG TALANG | F17: =COUNTIFS('Existing vs Saran'!$J$5:$J$210,A17) -> 2 | G17: =SUMIFS('Existing vs Saran'!$L$5:$L$210,'Existing vs Saran'!$J$5:$J$210,A17) -> 278.05 | H17: =COUNTIFS('Existing vs Saran'!$N$5:$N$210,A17) -> 2 | I17: =SUMIFS('Existing vs Saran'!$I$5:$I$210,'Existing vs Saran'!$N$5:$N$210,A17) -> 150.28 | J17: =I17-G17 -> -127.77 | K17: =IF(I17=0,"Tidak dipakai",IF(I17>'Parameter & Asumsi'!$B$8,"Berlebih",IF(I17<100,"Ringan","Wajar"))) -> Wajar
A18: 99 | B18: Julia Lara Zamzamy | C18: Rekrut baru | D18: 5 | E18: GUNUNG TALANG | F18: =COUNTIFS('Existing vs Saran'!$J$5:$J$210,A18) -> 1 | G18: =SUMIFS('Existing vs Saran'!$L$5:$L$210,'Existing vs Saran'!$J$5:$J$210,A18) -> 27.47 | H18: =COUNTIFS('Existing vs Saran'!$N$5:$N$210,A18) -> 1 | I18: =SUMIFS('Existing vs Saran'!$I$5:$I$210,'Existing vs Saran'!$N$5:$N$210,A18) -> 155.29 | J18: =I18-G18 -> 127.82 | K18: =IF(I18=0,"Tidak dipakai",IF(I18>'Parameter & Asumsi'!$B$8,"Berlebih",IF(I18<100,"Ringan","Wajar"))) -> Wajar | L18: Rekrut skema MENGINAP: sudah daftar tapi belum diplot; tawarkan menginap di kontrakan PANINGGAHAN (Kec. JUNJUNG SIRIH); Dilepas: beban terlalu kecil (< 60) -> wilayah digabung ke Sonya aldes fatma
A19: 101 | B19: Mardiati | C19: PPL existing | D19: 5 | E19: GUNUNG TALANG | F19: =COUNTIFS('Existing vs Saran'!$J$5:$J$210,A19) -> 3 | G19: =SUMIFS('Existing vs Saran'!$L$5:$L$210,'Existing vs Saran'!$J$5:$J$210,A19) -> 134.8 | H19: =COUNTIFS('Existing vs Saran'!$N$5:$N$210,A19) -> 3 | I19: =SUMIFS('Existing vs Saran'!$I$5:$I$210,'Existing vs Saran'!$N$5:$N$210,A19) -> 134.8 | J19: =I19-G19 -> 0 | K19: =IF(I19=0,"Tidak dipakai",IF(I19>'Parameter & Asumsi'!$B$8,"Berlebih",IF(I19<100,"Ringan","Wajar"))) -> Wajar
A20: 102 | B20: Mirvan Harvia | C20: PPL existing | D20: 5 | E20: GUNUNG TALANG | F20: =COUNTIFS('Existing vs Saran'!$J$5:$J$210,A20) -> 2 | G20: =SUMIFS('Existing vs Saran'!$L$5:$L$210,'Existing vs Saran'!$J$5:$J$210,A20) -> 274.11 | H20: =COUNTIFS('Existing vs Saran'!$N$5:$N$210,A20) -> 2 | I20: =SUMIFS('Existing vs Saran'!$I$5:$I$210,'Existing vs Saran'!$N$5:$N$210,A20) -> 146.55 | J20: =I20-G20 -> -127.56 | K20: =IF(I20=0,"Tidak dipakai",IF(I20>'Parameter & Asumsi'!$B$8,"Berlebih",IF(I20<100,"Ringan","Wajar"))) -> Wajar
A21: 106 | B21: Mustika Sari | C21: PPL existing | D21: 5 | E21: GUNUNG TALANG | F21: =COUNTIFS('Existing vs Saran'!$J$5:$J$210,A21) -> 1 | G21: =SUMIFS('Existing vs Saran'!$L$5:$L$210,'Existing vs Saran'!$J$5:$J$210,A21) -> 69.68 | H21: =COUNTIFS('Existing vs Saran'!$N$5:$N$210,A21) -> 1 | I21: =SUMIFS('Existing vs Saran'!$I$5:$I$210,'Existing vs Saran'!$N$5:$N$210,A21) -> 69.68 | J21: =I21-G21 -> 0 | K21: =IF(I21=0,"Tidak dipakai",IF(I21>'Parameter & Asumsi'!$B$8,"Berlebih",IF(I21<100,"Ringan","Wajar"))) -> Ringan
A22: 107 | B22: NAILA SABATINI | C22: PPL existing | D22: 5 | E22: GUNUNG TALANG | F22: =COUNTIFS('Existing vs Saran'!$J$5:$J$210,A22) -> 4 | G22: =SUMIFS('Existing vs Saran'!$L$5:$L$210,'Existing vs Saran'!$J$5:$J$210,A22) -> 95.15 | H22: =COUNTIFS('Existing vs Saran'!$N$5:$N$210,A22) -> 5 | I22: =SUMIFS('Existing vs Saran'!$I$5:$I$210,'Existing vs Saran'!$N$5:$N$210,A22) -> 214.82 | J22: =I22-G22 -> 119.67 | K22: =IF(I22=0,"Tidak dipakai",IF(I22>'Parameter & Asumsi'!$B$8,"Berlebih",IF(I22<100,"Ringan","Wajar"))) -> Wajar
