Workbook

Sheet Ringkasan
A1: Peserta pelatihan petugas pendataan bencana
A2: Syarat: sudah konfirmasi (bukan menolak) DAN sudah bergabung di grup WA. Data posisi 6 Okt 2026.
A4: Keterangan | B4: Jumlah
A5: Total baris di daftar (termasuk 2 PML organik & 8 sit-in) | B5: =COUNTA('Daftar Peserta'!$B$5:$B$97) -> 93
A6: - PML | B6: =COUNTIF('Daftar Peserta'!$C$5:$C$97,"PML") -> 19
A7: - PPL | B7: =COUNTIF('Daftar Peserta'!$C$5:$C$97,"PPL") -> 65
A8: - Tanpa peran (Mirvan Harvia, rangkap NTP) | B8: =COUNTIF('Daftar Peserta'!$C$5:$C$97,"-") -> 1
A9: PML organik di luar 78 (Ilham, Hariston) | B9: =COUNTIF('Daftar Peserta'!$M$5:$M$97,"Pegawai organik; di luar*") -> 2
A10: Peserta yang diusulkan masuk kelas | B10: =COUNT('Daftar Peserta'!$K$5:$K$97) -> 92
A11: Sit-in (pegawai organik) | B11: =COUNTIF('Daftar Peserta'!$C$5:$C$97,"SIT-IN") -> 8
A12: Kelas 1 (7 Okt 2026), termasuk sit-in | B12: =COUNTIF('Daftar Peserta'!$K$5:$K$97,1) -> 26
A13: Kelas 2 (8 Okt 2026), termasuk sit-in | B13: =COUNTIF('Daftar Peserta'!$K$5:$K$97,2) -> 23
A14: Kelas 3 (8 Okt 2026), termasuk sit-in | B14: =COUNTIF('Daftar Peserta'!$K$5:$K$97,3) -> 22
A15: Kelas 4 (8 Okt 2026), termasuk sit-in | B15: =COUNTIF('Daftar Peserta'!$K$5:$K$97,4) -> 21
A16: Panitia (2 per kelas) | B16: 8
A17: Anggota yang usulannya BEDA dari pilihan jadwalnya | B17: =COUNTIF('Daftar Peserta'!$L$5:$L$97,"Tidak") -> 16
A18: Memilih 7 Okt saja | B18: =COUNTIF('Daftar Peserta'!$H$5:$H$97,"7 Okt") -> 28
A19: Memilih 8 Okt saja | B19: =COUNTIF('Daftar Peserta'!$H$5:$H$97,"8 Okt") -> 35
A20: Memilih keduanya (7 & 8 Okt) | B20: =COUNTIF('Daftar Peserta'!$H$5:$H$97,"7 & 8 Okt") -> 15
A22: Per kecamatan asal | B22: Jumlah
A23: Gunung Talang | B23: =COUNTIF('Daftar Peserta'!$D$5:$D$97,A23) -> 24
A24: Ix Koto Sungai Lasi | B24: =COUNTIF('Daftar Peserta'!$D$5:$D$97,A24) -> 2
A25: Junjung Sirih | B25: =COUNTIF('Daftar Peserta'!$D$5:$D$97,A25) -> 11
A26: Kubung | B26: =COUNTIF('Daftar Peserta'!$D$5:$D$97,A26) -> 33
A27: Lembah Gumanti | B27: =COUNTIF('Daftar Peserta'!$D$5:$D$97,A27) -> 3
A28: Lembang Jaya | B28: =COUNTIF('Daftar Peserta'!$D$5:$D$97,A28) -> 1
A29: Pantai Cermin | B29: =COUNTIF('Daftar Peserta'!$D$5:$D$97,A29) -> 1
A30: X Koto Diatas | B30: =COUNTIF('Daftar Peserta'!$D$5:$D$97,A30) -> 1
A31: X Koto Singkarak | B31: =COUNTIF('Daftar Peserta'!$D$5:$D$97,A31) -> 15
A33: Catatan:
A34: 1. Tim = satu PML beserta PPL-nya menurut plotting saat ini; satu tim ditempatkan di gelombang & kelas yang sama.
A35: 2. Pilihan jadwal diambil dari isian petugas (7 Okt / 8 Okt / keduanya). Usulan meminimalkan anggota yang harus pindah dari pilihannya; lihat kolom "Sesuai pilihan?" dan sheet "Perlu Konfirmasi".
A36: 3. Aturan kelas 20-27 peserta: 84 peserta + 8 sit-in organik (8 Okt) = 92 orang = 4 kelas. Panitia 2 orang per kelas dihitung terpisah. Devi Kardila, Berni Desriyanti, Marvi Gusneriza, Leni Marta, dan Nila Sari ditambahkan atas arahan 6 Okt.
A37: 4. Masih ada ± 60 petugas yang sudah konfirmasi tetapi belum masuk grup WA; belum dihitung di sini.

Sheet Daftar Peserta
A1: Daftar petugas pendataan bencana: konfirmasi & sudah bergabung grup WA (posisi 6 Okt 2026)
A2: Gelombang 1 = 7 Okt 2026, Gelombang 2 = 8 Okt 2026 (dari pilihan jadwal petugas). Kolom Gelombang & Kelas = USULAN (Gelombang 1 = 7 Okt = Kelas 1; Gelombang 2 = 8 Okt = Kelas 2, 3 & 4); ubah angkanya, ringkasan ikut berubah.
A4: No | B4: Nama | C4: Peran | D4: Kecamatan | E4: Nagari | F4: No. HP | G4: Tim (PML) | H4: Pilihan jadwal | I4: Bergabung grup WA | J4: Gelombang | K4: Kelas | L4: Sesuai pilihan? | M4: Catatan
A5: 1 | B5: Leni Fatimah | C5: PPL | D5: X Koto Singkarak | E5: Koto Sani | F5: +6283178005904 | G5: Tanpa PML | H5: 7 Okt | I5: 05-10 08:04 | J5: 1 | K5: 1 | L5: =IF(OR(J5="",H5="(belum memilih)",H5="(organik)"),"",IF(OR(H5="7 & 8 Okt",H5="(kosong)",AND(H5="7 Okt",J5=1),AND(H5="8 Okt",J5=2)),"Ya","Tidak")) -> Ya | M5: Belum punya PML di plotting
A6: 2 | B6: Rahmad Hidayat | C6: PPL | D6: Lembah Gumanti | E6: Sungai Nanam | F6: +6281374176022 | G6: Tanpa PML | H6: 7 Okt | I6: 05-10 13:07 | J6: 1 | K6: 1 | L6: =IF(OR(J6="",H6="(belum memilih)",H6="(organik)"),"",IF(OR(H6="7 & 8 Okt",H6="(kosong)",AND(H6="7 Okt",J6=1),AND(H6="8 Okt",J6=2)),"Ya","Tidak")) -> Ya | M6: Belum punya PML di plotting
A7: 3 | B7: Dessy Meiyarni | C7: PML | D7: X Koto Singkarak | E7: Sumani | F7: +6282285844564 | G7: Tim Dessy Meiyarni | H7: 7 Okt | I7: 06-10 04:55 | J7: 1 | K7: 1 | L7: =IF(OR(J7="",H7="(belum memilih)",H7="(organik)"),"",IF(OR(H7="7 & 8 Okt",H7="(kosong)",AND(H7="7 Okt",J7=1),AND(H7="8 Okt",J7=2)),"Ya","Tidak")) -> Ya
A8: 4 | B8: Imilsi asgra varka | C8: PPL | D8: Kubung | E8: Koto Baru | F8: +6281370572508 | G8: Tim Dessy Meiyarni | H8: 7 Okt | I8: 04-10 15:53 | J8: 1 | K8: 1 | L8: =IF(OR(J8="",H8="(belum memilih)",H8="(organik)"),"",IF(OR(H8="7 & 8 Okt",H8="(kosong)",AND(H8="7 Okt",J8=1),AND(H8="8 Okt",J8=2)),"Ya","Tidak")) -> Ya
A9: 5 | B9: Hariston | C9: PML | D9: Kubung | G9: Tim Hariston (PML organik) | H9: (belum memilih) | I9: (organik) | J9: 1 | K9: 1 | L9: =IF(OR(J9="",H9="(belum memilih)",H9="(organik)"),"",IF(OR(H9="7 & 8 Okt",H9="(kosong)",AND(H9="7 Okt",J9=1),AND(H9="8 Okt",J9=2)),"Ya","Tidak")) | M9: Pegawai organik; di luar hitungan 78 petugas grup WA
A10: 6 | B10: Puji Putri | C10: PPL | D10: Junjung Sirih | E10: Muaro Pingai | F10: +6282382832500 | G10: Tim Hariston (PML organik) | H10: 7 Okt | I10: 04-10 15:53 | J10: 1 | K10: 1 | L10: =IF(OR(J10="",H10="(belum memilih)",H10="(organik)"),"",IF(OR(H10="7 & 8 Okt",H10="(kosong)",AND(H10="7 Okt",J10=1),AND(H10="8 Okt",J10=2)),"Ya","Tidak")) -> Ya
A11: 7 | B11: Reni Fatriani | C11: PPL | D11: Junjung Sirih | E11: Paninggahan | F11: +6281261728253 | G11: Tim Hariston (PML organik) | H11: 7 & 8 Okt | I11: 04-10 15:53 | J11: 1 | K11: 1 | L11: =IF(OR(J11="",H11="(belum memilih)",H11="(organik)"),"",IF(OR(H11="7 & 8 Okt",H11="(kosong)",AND(H11="7 Okt",J11=1),AND(H11="8 Okt",J11=2)),"Ya","Tidak")) -> Ya
A12: 8 | B12: Robi Alvian | C12: PPL | D12: Junjung Sirih | E12: Muaro Pingai | F12: +6282384030463 | G12: Tim Rifa Amelia (PML, menolak) | H12: 7 Okt | I12: 04-10 15:53 | J12: 1 | K12: 1 | L12: =IF(OR(J12="",H12="(belum memilih)",H12="(organik)"),"",IF(OR(H12="7 & 8 Okt",H12="(kosong)",AND(H12="7 Okt",J12=1),AND(H12="8 Okt",J12=2)),"Ya","Tidak")) -> Ya | M12: PML (Rifa Amelia) menolak - perlu PML baru
A13: 9 | B13: Widya elvera | C13: PML | D13: X Koto Singkarak | E13: Koto Sani | F13: +6285356931012 | G13: Tim Widya Elvera | H13: 8 Okt | I13: 04-10 15:53 | J13: 1 | K13: 1 | L13: =IF(OR(J13="",H13="(belum memilih)",H13="(organik)"),"",IF(OR(H13="7 & 8 Okt",H13="(kosong)",AND(H13="7 Okt",J13=1),AND(H13="8 Okt",J13=2)),"Ya","Tidak")) -> Tidak
A14: 10 | B14: Bayu pratama | C14: PPL | D14: X Koto Singkarak | E14: Sumani | F14: +6281311144431 | G14: Tim Widya Elvera | H14: 7 Okt | I14: 04-10 15:53 | J14: 1 | K14: 1 | L14: =IF(OR(J14="",H14="(belum memilih)",H14="(organik)"),"",IF(OR(H14="7 & 8 Okt",H14="(kosong)",AND(H14="7 Okt",J14=1),AND(H14="8 Okt",J14=2)),"Ya","Tidak")) -> Ya
A15: 11 | B15: Jahar Nas | C15: PPL | D15: X Koto Singkarak | E15: Koto Sani | F15: +6282391381273 | G15: Tim Widya Elvera | H15: 7 Okt | I15: 04-10 18:05 | J15: 1 | K15: 1 | L15: =IF(OR(J15="",H15="(belum memilih)",H15="(organik)"),"",IF(OR(H15="7 & 8 Okt",H15="(kosong)",AND(H15="7 Okt",J15=1),AND(H15="8 Okt",J15=2)),"Ya","Tidak")) -> Ya
A16: 12 | B16: Nur Aisyah | C16: PPL | D16: X Koto Singkarak | E16: Aripan | F16: +6282268555992 | G16: Tim Widya Elvera | H16: 7 Okt | I16: 06-10 04:55 | J16: 1 | K16: 1 | L16: =IF(OR(J16="",H16="(belum memilih)",H16="(organik)"),"",IF(OR(H16="7 & 8 Okt",H16="(kosong)",AND(H16="7 Okt",J16=1),AND(H16="8 Okt",J16=2)),"Ya","Tidak")) -> Ya
A17: 13 | B17: Leni Marta | C17: PPL | D17: Kubung | G17: Tim Widya Elvera | H17: (belum memilih) | I17: (belum bergabung) | J17: 1 | K17: 1 | L17: =IF(OR(J17="",H17="(belum memilih)",H17="(organik)"),"",IF(OR(H17="7 & 8 Okt",H17="(kosong)",AND(H17="7 Okt",J17=1),AND(H17="8 Okt",J17=2)),"Ya","Tidak")) | M17: Ditambahkan 6 Okt (status diterima); PML ditetapkan atas arahan; belum bergabung grup WA
A18: 14 | B18: Widya Verawati | C18: PML | D18: Kubung | E18: Koto Baru | F18: +6285274775368 | G18: Tim Widya Verawati | H18: 7 & 8 Okt | I18: 04-10 18:56 | J18: 1 | K18: 1 | L18: =IF(OR(J18="",H18="(belum memilih)",H18="(organik)"),"",IF(OR(H18="7 & 8 Okt",H18="(kosong)",AND(H18="7 Okt",J18=1),AND(H18="8 Okt",J18=2)),"Ya","Tidak")) -> Ya
A19: 15 | B19: Anggun Rahma Fajar | C19: PPL | D19: Kubung | E19: Koto Baru | F19: +6282285315252 | G19: Tim Widya Verawati | H19: 7 Okt | I19: 04-10 15:53 | J19: 1 | K19: 1 | L19: =IF(OR(J19="",H19="(belum memilih)",H19="(organik)"),"",IF(OR(H19="7 & 8 Okt",H19="(kosong)",AND(H19="7 Okt",J19=1),AND(H19="8 Okt",J19=2)),"Ya","Tidak")) -> Ya
A20: 16 | B20: Ayang Syafriani | C20: PPL | D20: Gunung Talang | E20: Talang | F20: +6283157632112 | G20: Tim Widya Verawati | H20: 7 Okt | I20: 04-10 20:39 | J20: 1 | K20: 1 | L20: =IF(OR(J20="",H20="(belum memilih)",H20="(organik)"),"",IF(OR(H20="7 & 8 Okt",H20="(kosong)",AND(H20="7 Okt",J20=1),AND(H20="8 Okt",J20=2)),"Ya","Tidak")) -> Ya
A21: 17 | B21: Dhini oktaviani | C21: PPL | D21: Gunung Talang | E21: Cupak | F21: +6282285112903 | G21: Tim Widya Verawati | H21: 8 Okt | I21: 04-10 17:30 | J21: 1 | K21: 1 | L21: =IF(OR(J21="",H21="(belum memilih)",H21="(organik)"),"",IF(OR(H21="7 & 8 Okt",H21="(kosong)",AND(H21="7 Okt",J21=1),AND(H21="8 Okt",J21=2)),"Ya","Tidak")) -> Tidak
A22: 18 | B22: Yurneti | C22: PML | D22: Kubung | E22: Selayo | F22: +6281266709257 | G22: Tim Yurneti | H22: 7 Okt | I22: 04-10 16:46 | J22: 1 | K22: 1 | L22: =IF(OR(J22="",H22="(belum memilih)",H22="(organik)"),"",IF(OR(H22="7 & 8 Okt",H22="(kosong)",AND(H22="7 Okt",J22=1),AND(H22="8 Okt",J22=2)),"Ya","Tidak")) -> Ya
A23: 19 | B23: Eka ramadani | C23: PPL | D23: Kubung | E23: Selayo | F23: +6289523016352 | G23: Tim Yurneti | H23: 7 Okt | I23: 04-10 17:39 | J23: 1 | K23: 1 | L23: =IF(OR(J23="",H23="(belum memilih)",H23="(organik)"),"",IF(OR(H23="7 & 8 Okt",H23="(kosong)",AND(H23="7 Okt",J23=1),AND(H23="8 Okt",J23=2)),"Ya","Tidak")) -> Ya
A24: 20 | B24: Fikri Mardiyani | C24: PPL | D24: Kubung | E24: Tanjuang Bingkuang | F24: +6288271538973 | G24: Tim Yurneti | H24: 8 Okt | I24: 04-10 17:32 | J24: 1 | K24: 1 | L24: =IF(OR(J24="",H24="(belum memilih)",H24="(organik)"),"",IF(OR(H24="7 & 8 Okt",H24="(kosong)",AND(H24="7 Okt",J24=1),AND(H24="8 Okt",J24=2)),"Ya","Tidak")) -> Tidak
A25: 21 | B25: Nelva Roza Oktakia | C25: PPL | D25: Kubung | E25: Selayo | F25: +6282171992943 | G25: Tim Yurneti | H25: 7 Okt | I25: 04-10 15:53 | J25: 1 | K25: 1 | L25: =IF(OR(J25="",H25="(belum memilih)",H25="(organik)"),"",IF(OR(H25="7 & 8 Okt",H25="(kosong)",AND(H25="7 Okt",J25=1),AND(H25="8 Okt",J25=2)),"Ya","Tidak")) -> Ya
A26: 22 | B26: Devi Kardila | C26: PPL | D26: Kubung | E26: Selayo | F26: +6282285034316 | G26: Tim Yurneti | H26: (belum memilih) | I26: (belum bergabung) | J26: 1 | K26: 1 | L26: =IF(OR(J26="",H26="(belum memilih)",H26="(organik)"),"",IF(OR(H26="7 & 8 Okt",H26="(kosong)",AND(H26="7 Okt",J26=1),AND(H26="8 Okt",J26=2)),"Ya","Tidak")) | M26: Ditambahkan atas arahan; status database masih menolak. Belum bergabung grup WA
A27: 23 | B27: Yusnita susanti | C27: PML | D27: Kubung | E27: Selayo | F27: +6282169634047 | G27: Tim Yusnita Susanti | H27: 8 Okt | I27: 04-10 17:30 | J27: 1 | K27: 1 | L27: =IF(OR(J27="",H27="(belum memilih)",H27="(organik)"),"",IF(OR(H27="7 & 8 Okt",H27="(kosong)",AND(H27="7 Okt",J27=1),AND(H27="8 Okt",J27=2)),"Ya","Tidak")) -> Tidak
A28: 24 | B28: Fuji erizka | C28: PPL | D28: Kubung | E28: Koto Baru | F28: +6285126568146 | G28: Tim Yusnita Susanti | H28: 7 & 8 Okt | I28: 04-10 15:53 | J28: 1 | K28: 1 | L28: =IF(OR(J28="",H28="(belum memilih)",H28="(organik)"),"",IF(OR(H28="7 & 8 Okt",H28="(kosong)",AND(H28="7 Okt",J28=1),AND(H28="8 Okt",J28=2)),"Ya","Tidak")) -> Ya
A29: 25 | B29: Idora Atia | C29: PPL | D29: Lembang Jaya | E29: Koto Anau | F29: +62895325906513 | G29: Tim Yusnita Susanti | H29: 7 Okt | I29: 04-10 15:53 | J29: 1 | K29: 1 | L29: =IF(OR(J29="",H29="(belum memilih)",H29="(organik)"),"",IF(OR(H29="7 & 8 Okt",H29="(kosong)",AND(H29="7 Okt",J29=1),AND(H29="8 Okt",J29=2)),"Ya","Tidak")) -> Ya
A30: 26 | B30: Mira Rozalinda | C30: PPL | D30: Kubung | E30: Koto Baru | F30: +6281374080153 | G30: Tim Yusnita Susanti | H30: 7 Okt | I30: 04-10 15:53 | J30: 1 | K30: 1 | L30: =IF(OR(J30="",H30="(belum memilih)",H30="(organik)"),"",IF(OR(H30="7 & 8 Okt",H30="(kosong)",AND(H30="7 Okt",J30=1),AND(H30="8 Okt",J30=2)),"Ya","Tidak")) -> Ya
A31: 27 | B31: Deswaty, SST. | C31: SIT-IN | D31: Gunung Talang | G31: Sit-in (pegawai organik) | H31: (organik) | I31: (organik) | J31: 2 | K31: 2 | L31: =IF(OR(J31="",H31="(belum memilih)",H31="(organik)"),"",IF(OR(H31="7 & 8 Okt",H31="(kosong)",AND(H31="7 Okt",J31=1),AND(H31="8 Okt",J31=2)),"Ya","Tidak")) | M31: Pegawai organik, ikut sit in (bukan peserta lapangan)
A32: 28 | B32: Riva Hestaria, A.Md. | C32: SIT-IN | D32: Gunung Talang | G32: Sit-in (pegawai organik) | H32: (organik) | I32: (organik) | J32: 2 | K32: 2 | L32: =IF(OR(J32="",H32="(belum memilih)",H32="(organik)"),"",IF(OR(H32="7 & 8 Okt",H32="(kosong)",AND(H32="7 Okt",J32=1),AND(H32="8 Okt",J32=2)),"Ya","Tidak")) | M32: Pegawai organik, ikut sit in (bukan peserta lapangan)
A33: 29 | B33: Ayu Sepriani | C33: PML | D33: X Koto Singkarak | E33: Koto Sani | F33: +6281266863316 | G33: Tim Ayu Sepriani | H33: 7 & 8 Okt | I33: 04-10 15:53 | J33: 2 | K33: 2 | L33: =IF(OR(J33="",H33="(belum memilih)",H33="(organik)"),"",IF(OR(H33="7 & 8 Okt",H33="(kosong)",AND(H33="7 Okt",J33=1),AND(H33="8 Okt",J33=2)),"Ya","Tidak")) -> Ya
A34: 30 | B34: Wina Zurlaili | C34: PPL | D34: Kubung | E34: Koto Baru | F34: +6282391089161 | G34: Tim Ayu Sepriani | H34: 8 Okt | I34: 04-10 15:53 | J34: 2 | K34: 2 | L34: =IF(OR(J34="",H34="(belum memilih)",H34="(organik)"),"",IF(OR(H34="7 & 8 Okt",H34="(kosong)",AND(H34="7 Okt",J34=1),AND(H34="8 Okt",J34=2)),"Ya","Tidak")) -> Ya
A35: 31 | B35: Budi Pernandes | C35: PML | D35: Junjung Sirih | E35: Paninggahan | F35: +6285271306838 | G35: Tim Budi Pernandes | H35: 7 Okt | I35: 04-10 15:53 | J35: 2 | K35: 2 | L35: =IF(OR(J35="",H35="(belum memilih)",H35="(organik)"),"",IF(OR(H35="7 & 8 Okt",H35="(kosong)",AND(H35="7 Okt",J35=1),AND(H35="8 Okt",J35=2)),"Ya","Tidak")) -> Tidak
A36: 32 | B36: Febri Handayani | C36: PPL | D36: X Koto Diatas | E36: Kuncia | F36: +6281365092925 | G36: Tim Budi Pernandes | H36: 8 Okt | I36: 05-10 18:07 | J36: 2 | K36: 2 | L36: =IF(OR(J36="",H36="(belum memilih)",H36="(organik)"),"",IF(OR(H36="7 & 8 Okt",H36="(kosong)",AND(H36="7 Okt",J36=1),AND(H36="8 Okt",J36=2)),"Ya","Tidak")) -> Ya
A37: 33 | B37: Indri septiadi | C37: PPL | D37: Gunung Talang | E37: Talang | F37: +6282285049476 | G37: Tim Budi Pernandes | H37: 8 Okt | I37: 05-10 12:08 | J37: 2 | K37: 2 | L37: =IF(OR(J37="",H37="(belum memilih)",H37="(organik)"),"",IF(OR(H37="7 & 8 Okt",H37="(kosong)",AND(H37="7 Okt",J37=1),AND(H37="8 Okt",J37=2)),"Ya","Tidak")) -> Ya
A38: 34 | B38: Minda Susanti | C38: PPL | D38: Junjung Sirih | E38: Paninggahan | F38: +6282288003542 | G38: Tim Budi Pernandes | H38: 7 Okt | I38: 05-10 13:07 | J38: 2 | K38: 2 | L38: =IF(OR(J38="",H38="(belum memilih)",H38="(organik)"),"",IF(OR(H38="7 & 8 Okt",H38="(kosong)",AND(H38="7 Okt",J38=1),AND(H38="8 Okt",J38=2)),"Ya","Tidak")) -> Tidak
A39: 35 | B39: Rini Nofsiska Sari | C39: PPL | D39: Junjung Sirih | F39: 081365430914 | G39: Tim Budi Pernandes | H39: 8 Okt | I39: 06-10 04:55 | J39: 2 | K39: 2 | L39: =IF(OR(J39="",H39="(belum memilih)",H39="(organik)"),"",IF(OR(H39="7 & 8 Okt",H39="(kosong)",AND(H39="7 Okt",J39=1),AND(H39="8 Okt",J39=2)),"Ya","Tidak")) -> Ya
A40: 36 | B40: Ferianto | C40: PML | D40: Kubung | E40: Koto Baru | F40: +6281374306238 | G40: Tim Ferianto | H40: 7 & 8 Okt | I40: 04-10 15:53 | J40: 2 | K40: 2 | L40: =IF(OR(J40="",H40="(belum memilih)",H40="(organik)"),"",IF(OR(H40="7 & 8 Okt",H40="(kosong)",AND(H40="7 Okt",J40=1),AND(H40="8 Okt",J40=2)),"Ya","Tidak")) -> Ya
A41: 37 | B41: Biki Wabihamdika | C41: PPL | D41: Kubung | E41: Gantuang Ciri | F41: +6285363471771 | G41: Tim Ferianto | H41: 8 Okt | I41: 05-10 12:08 | J41: 2 | K41: 2 | L41: =IF(OR(J41="",H41="(belum memilih)",H41="(organik)"),"",IF(OR(H41="7 & 8 Okt",H41="(kosong)",AND(H41="7 Okt",J41=1),AND(H41="8 Okt",J41=2)),"Ya","Tidak")) -> Ya
...

Sheet Usulan Sesi
A1: Usulan 4 kelas (aturan: 20-27 peserta per kelas termasuk sit-in; panitia 2 orang per kelas, di luar hitungan)
A3: Kelas | B3: Gelombang | C3: Tanggal | D3: Peserta lapangan | E3: Sit-in | F3: Total | G3: Batas 20-27 | H3: Panitia | I3: Tim (jumlah anggota)
A4: 1 | B4: 1 | C4: 7 Okt 2026 | D4: =COUNTIFS('Daftar Peserta'!$K$5:$K$97,1,'Daftar Peserta'!$C$5:$C$97,"<>SIT-IN") -> 26 | E4: =COUNTIFS('Daftar Peserta'!$K$5:$K$97,1,'Daftar Peserta'!$C$5:$C$97,"SIT-IN") -> 0 | F4: =D4+E4 -> 26 | G4: =IF(AND(F4>=20,F4<=27),"OK",IF(F4<20,"Kurang "&(20-F4),"Lebih "&(F4-27))) -> OK | H4: Mailani Putri + Arini Alva Syaadah | I4: Tanpa PML (2); Dessy Meiyarni (2); Hariston (PML organik) (3); Rifa Amelia (PML, menolak) (1); Widya Elvera (5); Widya Verawati (4); Yurneti (5); Yusnita Susanti (4)
A5: 2 | B5: 2 | C5: 8 Okt 2026 | D5: =COUNTIFS('Daftar Peserta'!$K$5:$K$97,2,'Daftar Peserta'!$C$5:$C$97,"<>SIT-IN") -> 21 | E5: =COUNTIFS('Daftar Peserta'!$K$5:$K$97,2,'Daftar Peserta'!$C$5:$C$97,"SIT-IN") -> 2 | F5: =D5+E5 -> 23 | G5: =IF(AND(F5>=20,F5<=27),"OK",IF(F5<20,"Kurang "&(20-F5),"Lebih "&(F5-27))) -> OK | H5: Faisal Siddiq + Dina Marizka | I5: Ayu Sepriani (2); Budi Pernandes (5); Ferianto (6); Irawita (6); Megawati (2)
A6: 3 | B6: 2 | C6: 8 Okt 2026 | D6: =COUNTIFS('Daftar Peserta'!$K$5:$K$97,3,'Daftar Peserta'!$C$5:$C$97,"<>SIT-IN") -> 19 | E6: =COUNTIFS('Daftar Peserta'!$K$5:$K$97,3,'Daftar Peserta'!$C$5:$C$97,"SIT-IN") -> 3 | F6: =D6+E6 -> 22 | G6: =IF(AND(F6>=20,F6<=27),"OK",IF(F6<20,"Kurang "&(20-F6),"Lebih "&(F6-27))) -> OK | H6: Oryza Maria Ulva + Nurafiza Thamrin | I6: Lia Angraini (4); Lucky Melan Sari (5); Mega Nana Yulianti (5); Saputra Ebel Feri (5)
A7: 4 | B7: 2 | C7: 8 Okt 2026 | D7: =COUNTIFS('Daftar Peserta'!$K$5:$K$97,4,'Daftar Peserta'!$C$5:$C$97,"<>SIT-IN") -> 18 | E7: =COUNTIFS('Daftar Peserta'!$K$5:$K$97,4,'Daftar Peserta'!$C$5:$C$97,"SIT-IN") -> 3 | F7: =D7+E7 -> 21 | G7: =IF(AND(F7>=20,F7<=27),"OK",IF(F7<20,"Kurang "&(20-F7),"Lebih "&(F7-27))) -> OK | H7: Alex Kandria + Witria Dasni | I7: Tanpa PML (1); Ilham (PML organik) (4); Usyenti (6); Yelli Novita Sari (2); Yeni Siswanti (5)
A8: Total | D8: =SUM(D4:D7) -> 84 | E8: =SUM(E4:E7) -> 8 | F8: =SUM(F4:F7) -> 92
A10: Nama panitia pada kolom Panitia adalah USUL (pegawai organik); silakan ganti. Kelas 1 = 7 Okt, kelas 2-4 = 8 Okt.

Sheet Panitia & Sit-in
A1: Peran | B1: Nama | C1: Kelas | D1: Tanggal
A2: Panitia | B2: Mailani Putri | C2: 1 | D2: 7 Okt 2026
A3: Panitia | B3: Arini Alva Syaadah | C3: 1 | D3: 7 Okt 2026
A4: Panitia | B4: Faisal Siddiq | C4: 2 | D4: 8 Okt 2026
A5: Panitia | B5: Dina Marizka | C5: 2 | D5: 8 Okt 2026
A6: Panitia | B6: Oryza Maria Ulva | C6: 3 | D6: 8 Okt 2026
A7: Panitia | B7: Nurafiza Thamrin | C7: 3 | D7: 8 Okt 2026
A8: Panitia | B8: Alex Kandria | C8: 4 | D8: 8 Okt 2026
A9: Panitia | B9: Witria Dasni | C9: 4 | D9: 8 Okt 2026
A10: Sit-in | B10: Deswaty, SST. | C10: 2 | D10: 8 Okt 2026
A11: Sit-in | B11: Riva Hestaria, A.Md. | C11: 2 | D11: 8 Okt 2026
A12: Sit-in | B12: Adriyanto | C12: 3 | D12: 8 Okt 2026
A13: Sit-in | B13: Lucia Veronica | C13: 3 | D13: 8 Okt 2026
... A17: Sit-in | B17: Adrianus | C17: 4 | D17: 8 Okt 2026

Sheet Perlu Konfirmasi
A1: Nama | B1: Peran | C1: Tim | D1: Pilihan jadwal | E1: Usulan gelombang | F1: Masalah
A2: Leni Fatimah | B2: PPL | C2: Tanpa PML | D2: 7 Okt | E2: 1 | F2: Belum punya PML di plotting
A3: Rahmad Hidayat | B3: PPL | C3: Tanpa PML | D3: 7 Okt | E3: 1 | F3: Belum punya PML di plotting
A4: Robi Alvian | B4: PPL | C4: Tim Rifa Amelia (PML, menolak) | D4: 7 Okt | E4: 1 | F4: PML (Rifa Amelia) menolak - perlu PML baru
A5: Widya elvera | B5: PML | C5: Tim Widya Elvera | D5: 8 Okt | E5: 1 | F5: Pilihan jadwalnya berbeda dari sesi timnya - tanyakan apakah bisa pindah
A6: Dhini oktaviani | B6: PPL | C6: Tim Widya Verawati | D6: 8 Okt | E6: 1 | F6: Pilihan jadwalnya berbeda dari sesi timnya - tanyakan apakah bisa pindah
A7: Fikri Mardiyani | B7: PPL | C7: Tim Yurneti | D7: 8 Okt | E7: 1 | F7: Pilihan jadwalnya berbeda dari sesi timnya - tanyakan apakah bisa pindah
A8: Yusnita susanti | B8: PML | C8: Tim Yusnita Susanti | D8: 8 Okt | E8: 1 | F8: Pilihan jadwalnya berbeda dari sesi timnya - tanyakan apakah bisa pindah
A9: Budi Pernandes | B9: PML | C9: Tim Budi Pernandes | D9: 7 Okt | E9: 2 | F9: Pilihan jadwalnya berbeda dari sesi timnya - tanyakan apakah bisa pindah
A10: Minda Susanti | B10: PPL | C10: Tim Budi Pernandes | D10: 7 Okt | E10: 2 | F10: Pilihan jadwalnya berbeda dari sesi timnya - tanyakan apakah bisa pindah
A11: Defitra Yeni | B11: PPL | C11: Tim Ferianto | D11: 7 Okt | E11: 2 | F11: Pilihan jadwalnya berbeda dari sesi timnya - tanyakan apakah bisa pindah
A12: Diana Endang Pratiwi | B12: PPL | C12: Tim Irawita | D12: 7 Okt | E12: 2 | F12: Pilihan jadwalnya berbeda dari sesi timnya - tanyakan apakah bisa pindah
A13: Sonya aldes fatma | B13: PPL | C13: Tim Irawita | D13: 7 Okt | E13: 2 | F13: Pilihan jadwalnya berbeda dari sesi timnya - tanyakan apakah bisa pindah
... A21: Anike Putri | B21: PPL | C21: Tim Yeni Siswanti | D21: 7 Okt | E21: 2 | F21: Pilihan jadwalnya berbeda dari sesi timnya - tanyakan apakah bisa pindah
A22: Mirvan Harvia | B22: - | C22: Dikeluarkan (rangkap SPDT NTP) | D22: 8 Okt | E22: - | F22: PPL SPDT NTP (rangkap) - sudah digantikan Ayang Syafriani; tidak diikutkan kelas
